Workbook

Sheet Fabó Editnek
A1: 2019. dolgozói étkezés adag száma
A2: December
A3: Megnevezés | B3: Ukód | C3: Xkód | D3: Darabszám
A4: Szarvas-Idős-bentlakásos | B4: U0000030331 | C4: X2000020 | D4: =SUMIF('Szarvas összesen'!$C$5:$H$102,C4,'Szarvas összesen'!$F$5:$F$102)+SUMIF('Szarvas összesen'!$C$5:$H$102,C4,'Szarvas összesen'!$H$5:$H$102) -> 437
A5: Szarvas-Szenv-bentlakásos | B5: U0000030332 | C5: X2000029 | D5: =SUMIF('Szarvas összesen'!$C$5:$H$102,C5,'Szarvas összesen'!$F$5:$F$102)+SUMIF('Szarvas összesen'!$C$5:$H$102,C5,'Szarvas összesen'!$H$5:$H$102) -> 89
A6: Szarvas-hajl-bentlakásos | B6: U0000030332 | C6: X2000030 | D6: =SUMIF('Szarvas összesen'!$C$5:$H$102,C6,'Szarvas összesen'!$F$5:$F$102)+SUMIF('Szarvas összesen'!$C$5:$H$102,C6,'Szarvas összesen'!$H$5:$H$102) -> 15
A7: Szarvas-konyha-bentlakásos | B7: U0000030332 | C7: X8800205 | D7: =SUMIF('Szarvas összesen'!$C$5:$H$102,C7,'Szarvas összesen'!$F$5:$F$102)+SUMIF('Szarvas összesen'!$C$5:$H$102,C7,'Szarvas összesen'!$H$5:$H$102) -> 74
A8: Vajda-Étkeztetés | B8: U0000030301 | C8: X2000004 | D8: =SUMIF('Vajda összesen'!$C$5:$H$97,C8,'Vajda összesen'!$F$5:$F$96)+SUMIF('Vajda összesen'!$C$5:$H$97,C8,'Vajda összesen'!$H$5:$H$97) -> 97
A9: Vajda-Házi segítségnyújtás | B9: U0000030301 | C9: X2000005 | D9: =SUMIF('Vajda összesen'!$C$5:$H$97,C9,'Vajda összesen'!$F$5:$F$96)+SUMIF('Vajda összesen'!$C$5:$H$97,C9,'Vajda összesen'!$H$5:$H$97) -> 81
A10: Vajda-Fogyatékos-nappali | B10: U0000030301 | C10: X2000010 | D10: =SUMIF('Vajda összesen'!$C$5:$H$97,C10,'Vajda összesen'!$F$5:$F$96)+SUMIF('Vajda összesen'!$C$5:$H$97,C10,'Vajda összesen'!$H$5:$H$97) -> 38
A11: Vajda-Támogató szolgálat | B11: U0000030301 | C11: X2000012 | D11: =SUMIF('Vajda összesen'!$C$5:$H$97,C11,'Vajda összesen'!$F$5:$F$96)+SUMIF('Vajda összesen'!$C$5:$H$97,C11,'Vajda összesen'!$H$5:$H$97) -> 31
A12: Vajda-Jelzőrendszer házi.seg | B12: U0000030301 | C12: X2000014 | D12: =SUMIF('Vajda összesen'!$C$5:$H$97,C12,'Vajda összesen'!$F$5:$F$96)+SUMIF('Vajda összesen'!$C$5:$H$97,C12,'Vajda összesen'!$H$5:$H$97) -> 0
A13: Vajda-Idős-bentlakásos | B13: U0000030311 | C13: X2000020 | D13: =SUMIF('Vajda összesen'!$C$5:$H$97,C13,'Vajda összesen'!$F$5:$F$96)+SUMIF('Vajda összesen'!$C$5:$H$97,C13,'Vajda összesen'!$H$5:$H$97) -> 16
A14: Vajda-Demens-nappali | B14: U0000030301 | C14: X2000025 | D14: =SUMIF('Vajda összesen'!$C$5:$H$97,C14,'Vajda összesen'!$F$5:$F$96)+SUMIF('Vajda összesen'!$C$5:$H$97,C14,'Vajda összesen'!$H$5:$H$97) -> 34
A15: Vajda-Szenv.-nappali | B15: U0000030301 | C15: X2000026 | D15: =SUMIF('Vajda összesen'!$C$5:$H$97,C15,'Vajda összesen'!$F$5:$F$96)+SUMIF('Vajda összesen'!$C$5:$H$97,C15,'Vajda összesen'!$H$5:$H$97) -> 0
A16: Vajda-Közösségi el. Szenv. | B16: U0000030301 | C16: X2000037 | D16: =SUMIF('Vajda összesen'!$C$5:$H$97,C16,'Vajda összesen'!$F$5:$F$96)+SUMIF('Vajda összesen'!$C$5:$H$97,C16,'Vajda összesen'!$H$5:$H$97) -> 0
A17: Vajda-Otthoni Szakápolás | B17: U0000030301 | C17: X2100001 | D17: =SUMIF('Vajda összesen'!$C$5:$H$97,C17,'Vajda összesen'!$F$5:$F$96)+SUMIF('Vajda összesen'!$C$5:$H$97,C17,'Vajda összesen'!$H$5:$H$97) -> 0
A18: Vajda-Igazgatóság | B18: U0000030301 | C18: X8800101 | D18: =SUMIF('Vajda összesen'!$C$5:$H$97,C18,'Vajda összesen'!$F$5:$F$96)+SUMIF('Vajda összesen'!$C$5:$H$97,C18,'Vajda összesen'!$H$5:$H$97) -> 117
A19: Vajda-Idős korúak el.-nappali | B19: U0000030301 | C19: X2000006 | D19: =SUMIF('Vajda összesen'!$C$5:$H$97,C19,'Vajda összesen'!$F$5:$F$96)+SUMIF('Vajda összesen'!$C$5:$H$97,C19,'Vajda összesen'!$H$5:$H$97) -> 18
A20: Örménykút-Házi segítség | B20: U0000030302 | C20: X2000005 | D20: =SUMIF('Örménykút összesen'!$C$5:$H$9,C20,'Örménykút összesen'!$F$5:$F$9)+SUMIF('Örménykút összesen'!$C$5:$H$9,C20,'Örménykút összesen'!$H$5:$H$9) -> 20
A21: Örménykút-Időskorúak el. -nappali | B21: U0000030302 | C21: X2000006 | D21: =SUMIF('Örménykút összesen'!$C$5:$H$9,C21,'Örménykút összesen'!$F$5:$F$9)+SUMIF('Örménykút összesen'!$C$5:$H$9,C21,'Örménykút összesen'!$H$5:$H$9) -> 20
A22: Középhalom-Időskorúak el. -nappali | B22: U0000030303 | C22: X2000006 | D22: =SUMIF('Középhalom összesen'!$C$5:$H$8,C22,'Középhalom összesen'!$F$5:$F$8)+SUMIF('Középhalom összesen'!$C$5:$H$8,C22,'Középhalom összesen'!$H$5:$H$8) -> 0
A23: Középhalom-Tanya Gondnok | B23: U0000030303 | C23: X2000032 | D23: =SUMIF('Középhalom összesen'!$C$5:$H$8,C23,'Középhalom összesen'!$F$5:$F$8)+SUMIF('Középhalom összesen'!$C$5:$H$8,C23,'Középhalom összesen'!$H$5:$H$8) -> 20
A24: Furugy-Időskorúak el. -nappali | B24: U0000030304 | C24: X2000006 | D24: =SUMIF('Furugy összesen'!$C$5:$H$7,C24,'Furugy összesen'!$F$5:$F$7)+SUMIF('Furugy összesen'!$C$5:$H$7,C24,'Furugy összesen'!$H$5:$H$7) -> 0
A25: Szent László-Támogatott lakhatás szenv. | B25: U0000030305 | C25: X2000050 | D25: =SUMIF('Szent László összesen'!$C$5:$H$8,C25,'Szent László összesen'!$F$5:$F$8)+SUMIF('Szent László összesen'!$C$5:$H$8,C25,'Szent László összesen'!$H$5:$H$8) -> 29
A26: Csabacsűd-Idős-bentlakásos | B26: U0000030321 | C26: X2000020 | D26: =SUMIF('Csabacsűd összesen'!$C$5:$H$17,C26,'Csabacsűd összesen'!$F$5:$F$17)+SUMIF('Csabacsűd összesen'!$C$5:$H$17,C26,'Csabacsűd összesen'!$H$5:$H$17) -> 0
A27: Összesen: | B27: =SUM(D4:D26) -> 1136
A28: Táblákból összesen: | B28: ='Furugy összesen'!F7+'Furugy összesen'!H7+'Szarvas összesen'!F103+'Szarvas összesen'!H103+'Középhalom összesen'!F9+'Középhalom összesen'!H9+'Szent László összesen'!F7+'Szent László összesen'!H7+'Csabacsűd összesen'!F18+'Csabacsűd összesen'!H18+'Örménykút összesen'!F10+'Örménykút összesen'!H10+'Vajda összesen'!F98+'Vajda összesen'!H98 -> 1136
A29: Szakácsoknak összesen: | B29: =Szakácsoknak!B5 -> 1136
A30: Különbség: | B30: =2*B27-B28-B29 -> 0
A33: Készítette:
A35: Domján Balázsné

Sheet Szakácsoknak
A1: Szakácsoknak
A2: Dátum | B2: 1. | C2: 2. | D2: 3. | E2: 4. | F2: 5. | G2: 6. | H2: 7. | I2: 8. | J2: 9. | K2: 10. | L2: 11. | M2: 12. | N2: 13. | O2: 14. | P2: 15. | Q2: 16. | R2: 17. | S2: 18. | T2: 19. | U2: 20. | V2: 21. | W2: 22. | X2: 23. | Y2: 24. | Z2: 25. | AA2: 26. | AB2: 27. | AC2: 28. | AD2: 29. | AE2: 30. | AF2: 31.
A3: Adagszám | B3: =Furugy!B12+Szarvas!B241+Tanulók!B38+Középhalom!B21+'Szent László'!B12+Csabacsűd!B35+Örménykút!B25+Vajda!B244 -> 7 | C3: =Furugy!C12+Szarvas!C241+Tanulók!C38+Középhalom!C21+'Szent László'!C12+Csabacsűd!C35+Örménykút!C25+Vajda!C244 -> 68 | D3: =Furugy!D12+Szarvas!D241+Tanulók!D38+Középhalom!D21+'Szent László'!D12+Csabacsűd!D35+Örménykút!D25+Vajda!D244 -> 66 | E3: =Furugy!E12+Szarvas!E241+Tanulók!E38+Középhalom!E21+'Szent László'!E12+Csabacsűd!E35+Örménykút!E25+Vajda!E244 -> 50 | F3: =Furugy!F12+Szarvas!F241+Tanulók!F38+Középhalom!F21+'Szent László'!F12+Csabacsűd!F35+Örménykút!F25+Vajda!F244 -> 55 | G3: =Furugy!G12+Szarvas!G241+Tanulók!G38+Középhalom!G21+'Szent László'!G12+Csabacsűd!G35+Örménykút!G25+Vajda!G244 -> 75 | H3: =Furugy!H12+Szarvas!H241+Tanulók!H38+Középhalom!H21+'Szent László'!H12+Csabacsűd!H35+Örménykút!H25+Vajda!H244 -> 28 | I3: =Furugy!I12+Szarvas!I241+Tanulók!I38+Középhalom!I21+'Szent László'!I12+Csabacsűd!I35+Örménykút!I25+Vajda!I244 -> 7 | ... AF3: =Furugy!AF12+Szarvas!AF241+Tanulók!AF38+Középhalom!AF21+'Szent László'!AF12+Csabacsűd!AF35+Örménykút!AF25+Vajda!AF244 -> 20
B5: =SUM(B3:AF3) -> 1136

Sheet Furugy
A1: Nevek | B1: 1 | C1: 2 | D1: 3 | E1: 4 | F1: 5 | G1: 6 | H1: 7 | I1: 8 | J1: 9 | K1: 10 | L1: 11 | M1: 12 | N1: 13 | O1: 14 | P1: 15 | Q1: 16 | R1: 17 | S1: 18 | T1: 19 | U1: 20 | V1: 21 | W1: 22 | X1: 23 | Y1: 24 | Z1: 25 | AA1: 26 | AB1: 27 | AC1: 28 | AD1: 29 | AE1: 30 | AF1: 31 | AG1: Összesen
A2: Dolgozói ebéd(460)
A3: Furugy
A4: Szemes Józsefné | AG4: =SUM(B4:AF4) -> 0
AG5: =SUM(B5:AF5) -> 0
A6: Összesen | B6: =SUM(B4:B5) -> 0 | C6: =SUM(C4:C5) -> 0 | D6: =SUM(D4:D5) -> 0 | E6: =SUM(E4:E5) -> 0 | F6: =SUM(F4:F5) -> 0 | G6: =SUM(G4:G5) -> 0 | H6: =SUM(H4:H5) -> 0 | I6: =SUM(I4:I5) -> 0 | ... AG6: =SUM(AG4:AG5) -> 0
A7: Dolgozói ebéd(380)
A8: Furugy
A9: =A4 -> Szemes Józsefné | AG9: =SUM(B9:AF9) -> 0
A10: =A5 -> 0 | AG10: =SUM(B10:AF10) -> 0
A11: Összesen | B11: =SUM(B9:B10) -> 0 | C11: =SUM(C9:C10) -> 0 | D11: =SUM(D9:D10) -> 0 | E11: =SUM(E9:E10) -> 0 | F11: =SUM(F9:F10) -> 0 | G11: =SUM(G9:G10) -> 0 | H11: =SUM(H9:H10) -> 0 | I11: =SUM(I9:I10) -> 0 | ... AG11: =SUM(AG9:AG10) -> 0
A12: Napi összesen: | B12: =SUM(B6,B11) -> 0 | C12: =SUM(C6,C11) -> 0 | D12: =SUM(D6,D11) -> 0 | E12: =SUM(E6,E11) -> 0 | F12: =SUM(F6,F11) -> 0 | G12: =SUM(G6,G11) -> 0 | H12: =SUM(H6,H11) -> 0 | I12: =SUM(I6,I11) -> 0 | ... AF12: =SUM(AF6,AF11) -> 0 | AG12: =AG11+AG6 -> 0

Sheet Furugy összesen
A1: Adatszolgáltatás számlázáshoz | H1: Dolgozói Étkeztetés | I1: Dátum
A2: Ótemplomi Szeretetszolgálat | H2: Domján Balázsné
A3: Étkeztetésben részesülők. | E3: Kedvezményezett ebéd | G3: Dolgozói ebéd
A4: SSz. | B4: Név | C4: xkód | D4: ukód | E4: Bruttó egységár(Ft) | F4: Adagszám(db) | G4: Bruttó egységár (Ft) | H4: Adagszám (db) | I4: Számlázandó összesen (Ft)
A5: 1. | B5: =Furugy!A4 -> Szemes Józsefné | C5: =VLOOKUP(B5,többinévsor!$A$2:$C$28,2,FALSE) -> X2000006 | D5: =VLOOKUP(B5,többinévsor!$A$2:$C$28,3,FALSE) -> U000030304 | E5: 380 | F5: =Furugy!AG9 -> 0 | G5: 460 | H5: =Furugy!AG4 -> 0 | I5: =(E5*F5)+(G5*H5) -> 0
A6: 2. | B6: =Furugy!A5 -> 0 | C6: =VLOOKUP(B6,többinévsor!$A$2:$C$28,2,FALSE) -> #N/A | D6: =VLOOKUP(B6,többinévsor!$A$2:$C$28,3,FALSE) -> #N/A | E6: 380 | F6: =Furugy!AG10 -> 0 | G6: 460 | H6: =Furugy!AG5 -> 0 | I6: =(E6*F6)+(G6*H6) -> 0
B7: Összesen | F7: =SUM(F5:F6) -> 0 | H7: =SUM(H5:H6) -> 0 | I7: =SUM(I5:I6) -> 0
B11: Kelt:Szarvas,2018 május 31. | H11: Készítette:Domján Balázsné

Sheet Szarvas
A1: Nevek | B1: 1 | C1: 2 | D1: 3 | E1: 4 | F1: 5 | G1: 6 | H1: 7 | I1: 8 | J1: 9 | K1: 10 | L1: 11 | M1: 12 | N1: 13 | O1: 14 | P1: 15 | Q1: 16 | R1: 17 | S1: 18 | T1: 19 | U1: 20 | V1: 21 | W1: 22 | X1: 23 | Y1: 24 | Z1: 25 | AA1: 26 | AB1: 27 | AC1: 28 | AD1: 29 | AE1: 30 | AF1: 31 | AG1: Összesen
A2: Dolgozói ebéd(460)
A3: Földszint(460)
A4: Klimaj Zoltánné | AG4: =SUM(B4:AF4) -> 0
A5: Kozák Lászlóné | AG5: =SUM(B5:AF5) -> 0
A6: Lestyán Goda Jánosné | AG6: =SUM(B6:AF6) -> 0
A7: Nemesné Kovács Mónika | AG7: =SUM(B7:AF7) -> 0
A8: Nevelősné Mikus Piroska | AG8: =SUM(B8:AF8) -> 0
A9: Palyov Alexandra | AG9: =SUM(B9:AF9) -> 0
A10: Stuller Istvánné | AG10: =SUM(B10:AF10) -> 0
A11: Szekretár Anna | AG11: =SUM(B11:AF11) -> 0
A12: Takács Józsefné | AG12: =SUM(B12:AF12) -> 0
A13: Tusjak Mariann | AG13: =SUM(B13:AF13) -> 0
A14: Összesen | B14: =SUM(B4:B13) -> 0 | C14: =SUM(C4:C13) -> 0 | D14: =SUM(D4:D13) -> 0 | E14: =SUM(E4:E13) -> 0 | F14: =SUM(F4:F13) -> 0 | G14: =SUM(G4:G13) -> 0 | H14: =SUM(H4:H13) -> 0 | I14: =SUM(I4:I13) -> 0 | ... AF14: =SUM(AF4:AF13) -> 0 | AG14: =SUM(B14:AF14) -> 0
A15: Emelet(460)
A16: Aradi Orsolya | AG16: =SUM(B16:AF16) -> 0
A17: Barabás György | AG17: =SUM(B17:AF17) -> 0
A18: Dudás Renáta | AG18: =SUM(B18:AF18) -> 0
A19: Gazsó Linda | AG19: =SUM(B19:AF19) -> 0
A20: Ivacska Istvánné | AG20: =SUM(B20:AF20) -> 0
A21: Kovács Éva | AG21: =SUM(B21:AF21) -> 0
A22: Kovács Viktoria | AG22: =SUM(B22:AF22) -> 0
A23: Körmendi Szilvia | AG23: =SUM(B23:AF23) -> 0
A24: Lólé Margit | AG24: =SUM(B24:AF24) -> 0
A25: Medvegyné Jelen Anna | AG25: =SUM(B25:AF25) -> 0
A26: Nagy Zoltán | AG26: =SUM(B26:AF26) -> 0
A27: Szirony László | AG27: =SUM(B27:AF27) -> 0
A28: Virágh Mária | AG28: =SUM(B28:AF28) -> 0
A29: Összesen | B29: =SUM(B16:B28) -> 0 | C29: =SUM(C16:C28) -> 0 | D29: =SUM(D16:D28) -> 0 | E29: =SUM(E16:E28) -> 0 | F29: =SUM(F16:F28) -> 0 | G29: =SUM(G16:G28) -> 0 | H29: =SUM(H16:H28) -> 0 | I29: =SUM(I16:I28) -> 0 | ... AF29: =SUM(AF16:AF28) -> 0 | AG29: =SUM(B29:AF29) -> 0
A30: Demens(460)
A31: Balogh Beáta | AG31: =SUM(B31:AF31) -> 0
A32: Balogh Mária | AG32: =SUM(B32:AF32) -> 0
A33: Gyuris Krisztina | AG33: =SUM(B33:AF33) -> 0
A34: Kondacsné Alt Piroska | AG34: =SUM(B34:AF34) -> 0
A35: Kőfalvi Roland | AG35: =SUM(B35:AF35) -> 0
A36: Kusnyarné stefancsik Zsuzsanna | AG36: =SUM(B36:AF36) -> 0
A37: Laurikné Szakács Katalin | AG37: =SUM(B37:AF37) -> 0
A38: Borgulya Szilvia | AG38: =SUM(B38:AF38) -> 0
A39: Lévai Rita | AG39: =SUM(B39:AF39) -> 0
A40: Litauszki János | AG40: =SUM(B40:AF40) -> 0
...

Sheet Tanulók
A1: Nevek | B1: 1 | C1: 2 | D1: 3 | E1: 4 | F1: 5 | G1: 6 | H1: 7 | I1: 8 | J1: 9 | K1: 10 | L1: 11 | M1: 12 | N1: 13 | O1: 14 | P1: 15 | Q1: 16 | R1: 17 | S1: 18 | T1: 19 | U1: 20 | V1: 21 | W1: 22 | X1: 23 | Y1: 24 | Z1: 25 | AA1: 26 | AB1: 27 | AC1: 28 | AD1: 29 | AE1: 30 | AF1: 31 | AG1: Összesen
A2: Dolgozói ebéd(460)
A3: Tanulók
A4: Kaposi Bettina | AG4: =SUM(B4:AF4) -> 0
A5: Deákné Burai Anikó | AG5: =SUM(B5:AF5) -> 0
A6: Papp Katalin | AG6: =SUM(B6:AF6) -> 0
A7: Tyichi Szilárd | AG7: =SUM(B7:AF7) -> 0
A8: Gombár György | AG8: =SUM(B8:AF8) -> 0
A9: Pápai Vivien | AG9: =SUM(B9:AF9) -> 0
A10: Gergye Brigitta | AG10: =SUM(B10:AF10) -> 0
A11: Szopka Anikó | AG11: =SUM(B11:AF11) -> 0
A12: Aradi Orsolya | AG12: =SUM(B12:AF12) -> 0
A13: Csikós Zsanett | AG13: =SUM(B13:AF13) -> 0
AG14: =SUM(B14:AF14) -> 0
AG15: =SUM(B15:AF15) -> 0
AG16: =SUM(B16:AF16) -> 0
AG17: =SUM(B17:AF17) -> 0
AG18: =SUM(B18:AF18) -> 0
A19: Összesen | B19: =SUM(B4:B18) -> 0 | C19: =SUM(C4:C18) -> 0 | D19: =SUM(D4:D18) -> 0 | E19: =SUM(E4:E18) -> 0 | F19: =SUM(F4:F18) -> 0 | G19: =SUM(G4:G18) -> 0 | H19: =SUM(H4:H18) -> 0 | I19: =SUM(I4:I18) -> 0 | ... AG19: =SUM(AG4:AG18) -> 0
A20: Dolgozói ebéd(380)
A21: Tanulók
A22: =A4 -> Kaposi Bettina | AG22: =SUM(B22:AF22) -> 0
A23: =A5 -> Deákné Burai Anikó | AG23: =SUM(B23:AF23) -> 0
A24: =A6 -> Papp Katalin | AG24: =SUM(B24:AF24) -> 0
A25: =A7 -> Tyichi Szilárd | AG25: =SUM(B25:AF25) -> 0
A26: =A8 -> Gombár György | AG26: =SUM(B26:AF26) -> 0
A27: =A9 -> Pápai Vivien | AG27: =SUM(B27:AF27) -> 0
A28: =A10 -> Gergye Brigitta | AG28: =SUM(B28:AF28) -> 0
A29: =A11 -> Szopka Anikó | AG29: =SUM(B29:AF29) -> 0
A30: =A12 -> Aradi Orsolya | AG30: =SUM(B30:AF30) -> 0
A31: =A13 -> Csikós Zsanett | AG31: =SUM(B31:AF31) -> 0
A32: =A14 -> 0 | AG32: =SUM(B32:AF32) -> 0
A33: =A15 -> 0 | AG33: =SUM(B33:AF33) -> 0
... A36: =A18 -> 0 | AG36: =SUM(B36:AF36) -> 0
A37: Összesen | B37: =SUM(B22:B36) -> 0 | C37: =SUM(C22:C36) -> 0 | D37: =SUM(D22:D36) -> 0 | E37: =SUM(E22:E36) -> 0 | F37: =SUM(F22:F36) -> 0 | G37: =SUM(G22:G36) -> 0 | H37: =SUM(H22:H36) -> 0 | I37: =SUM(I22:I36) -> 0 | ... AG37: =SUM(AG22:AG36) -> 0
A38: Napi összesen: | B38: =SUM(B19,B37) -> 0 | C38: =SUM(C19,C37) -> 0 | D38: =SUM(D19,D37) -> 0 | E38: =SUM(E19,E37) -> 0 | F38: =SUM(F19,F37) -> 0 | G38: =SUM(G19,G37) -> 0 | H38: =SUM(H19,H37) -> 0 | I38: =SUM(I19,I37) -> 0 | ... AF38: =SUM(AF19,AF37) -> 0

Sheet Szarvas összesen
A1: Adatszolgáltatás számlázáshoz | H1: Dolgozói Étkeztetés | I1: SZEPTEMBER
A2: Ótemplomi Szeretetszolgálat | H2: Domján Balázsné
A3: Étkeztetésben részesülők. | E3: Kedvezményezett ebéd | G3: Dolgozói ebéd
A4: SSz. | B4: Név | C4: Xkód | D4: ukód | E4: Bruttó egységár(Ft) | F4: Adagszám(db) | G4: Bruttó egységár (Ft) | H4: Adagszám (db) | I4: Számlázandó összesen (Ft)
A5: 1 | B5: Klimaj Zoltánné | C5: =VLOOKUP(B5,Szarvasnévsor!A:C,2,FALSE) -> X2000020 | D5: =VLOOKUP(B5,Szarvasnévsor!A:C,3,FALSE) -> U0000030331 | E5: 380 | F5: =VLOOKUP(B5,Szarvas!$A$123:$AG$245,33,FALSE) -> 3 | G5: 460 | H5: =VLOOKUP(B5,Szarvas!$A$3:$AG$120,33,FALSE) -> 0 | I5: =(E5*F5)+(G5*H5) -> 1140
A6: 2 | B6: Kozák Lászlóné | C6: =VLOOKUP(B6,Szarvasnévsor!A:C,2,FALSE) -> X2000020 | D6: =VLOOKUP(B6,Szarvasnévsor!A:C,3,FALSE) -> U0000030331 | E6: 380 | F6: =VLOOKUP(B6,Szarvas!$A$123:$AG$245,33,FALSE) -> 3 | G6: 460 | H6: =VLOOKUP(B6,Szarvas!$A$3:$AG$120,33,FALSE) -> 0 | I6: =(E6*F6)+(G6*H6) -> 1140
A7: 3 | B7: Nemesné Kovács Mónika | C7: =VLOOKUP(B7,Szarvasnévsor!A:C,2,FALSE) -> X2000020 | D7: =VLOOKUP(B7,Szarvasnévsor!A:C,3,FALSE) -> U0000030331 | E7: 380 | F7: =VLOOKUP(B7,Szarvas!$A$123:$AG$245,33,FALSE) -> 3 | G7: 460 | H7: =VLOOKUP(B7,Szarvas!$A$3:$AG$120,33,FALSE) -> 0 | I7: =(E7*F7)+(G7*H7) -> 1140
A8: 4 | B8: Nevelősné Mikus Piroska | C8: =VLOOKUP(B8,Szarvasnévsor!A:C,2,FALSE) -> X2000020 | D8: =VLOOKUP(B8,Szarvasnévsor!A:C,3,FALSE) -> U0000030331 | E8: 380 | F8: =VLOOKUP(B8,Szarvas!$A$123:$AG$245,33,FALSE) -> 3 | G8: 460 | H8: =VLOOKUP(B8,Szarvas!$A$3:$AG$120,33,FALSE) -> 0 | I8: =(E8*F8)+(G8*H8) -> 1140
A9: 5 | B9: Palyov Alexandra | C9: =VLOOKUP(B9,Szarvasnévsor!A:C,2,FALSE) -> X2000020 | D9: =VLOOKUP(B9,Szarvasnévsor!A:C,3,FALSE) -> U0000030331 | E9: 380 | F9: =VLOOKUP(B9,Szarvas!$A$123:$AG$245,33,FALSE) -> 2 | G9: 460 | H9: =VLOOKUP(B9,Szarvas!$A$3:$AG$120,33,FALSE) -> 0 | I9: =(E9*F9)+(G9*H9) -> 760
A10: 6 | B10: Stuller Istvánné | C10: =VLOOKUP(B10,Szarvasnévsor!A:C,2,FALSE) -> X2000020 | D10: =VLOOKUP(B10,Szarvasnévsor!A:C,3,FALSE) -> U0000030331 | E10: 380 | F10: =VLOOKUP(B10,Szarvas!$A$123:$AG$245,33,FALSE) -> 5 | G10: 460 | H10: =VLOOKUP(B10,Szarvas!$A$3:$AG$120,33,FALSE) -> 0 | I10: =(E10*F10)+(G10*H10) -> 1900
A11: 7 | B11: Szekretár Anna | C11: =VLOOKUP(B11,Szarvasnévsor!A:C,2,FALSE) -> X2000020 | D11: =VLOOKUP(B11,Szarvasnévsor!A:C,3,FALSE) -> U0000030331 | E11: 380 | F11: =VLOOKUP(B11,Szarvas!$A$123:$AG$245,33,FALSE) -> 4 | G11: 460 | H11: =VLOOKUP(B11,Szarvas!$A$3:$AG$120,33,FALSE) -> 0 | I11: =(E11*F11)+(G11*H11) -> 1520
A12: 8 | B12: Takács Józsefné | C12: =VLOOKUP(B12,Szarvasnévsor!A:C,2,FALSE) -> X2000020 | D12: =VLOOKUP(B12,Szarvasnévsor!A:C,3,FALSE) -> U0000030331 | E12: 380 | F12: =VLOOKUP(B12,Szarvas!$A$123:$AG$245,33,FALSE) -> 0 | G12: 460 | H12: =VLOOKUP(B12,Szarvas!$A$3:$AG$120,33,FALSE) -> 0 | I12: =(E12*F12)+(G12*H12) -> 0
A13: 9 | B13: Tusjak Mariann | C13: =VLOOKUP(B13,Szarvasnévsor!A:C,2,FALSE) -> X2000020 | D13: =VLOOKUP(B13,Szarvasnévsor!A:C,3,FALSE) -> U0000030331 | E13: 380 | F13: =VLOOKUP(B13,Szarvas!$A$123:$AG$245,33,FALSE) -> 4 | G13: 460 | H13: =VLOOKUP(B13,Szarvas!$A$3:$AG$120,33,FALSE) -> 0 | I13: =(E13*F13)+(G13*H13) -> 1520
A14: 10 | B14: Aradi Orsolya | C14: =VLOOKUP(B14,Szarvasnévsor!A:C,2,FALSE) -> X2000020 | D14: =VLOOKUP(B14,Szarvasnévsor!A:C,3,FALSE) -> U0000030331 | E14: 380 | F14: =VLOOKUP(B14,Szarvas!$A$123:$AG$245,33,FALSE) -> 0 | G14: 460 | H14: =VLOOKUP(B14,Szarvas!$A$3:$AG$120,33,FALSE) -> 0 | I14: =(E14*F14)+(G14*H14) -> 0
A15: 11 | B15: Dudás Renáta | C15: =VLOOKUP(B15,Szarvasnévsor!A:C,2,FALSE) -> X2000020 | D15: =VLOOKUP(B15,Szarvasnévsor!A:C,3,FALSE) -> U0000030331 | E15: 380 | F15: =VLOOKUP(B15,Szarvas!$A$123:$AG$245,33,FALSE) -> 2 | G15: 460 | H15: =VLOOKUP(B15,Szarvas!$A$3:$AG$120,33,FALSE) -> 0 | I15: =(E15*F15)+(G15*H15) -> 760
A16: 12 | B16: Gazsó Linda | C16: =VLOOKUP(B16,Szarvasnévsor!A:C,2,FALSE) -> X2000020 | D16: =VLOOKUP(B16,Szarvasnévsor!A:C,3,FALSE) -> U0000030331 | E16: 380 | F16: =VLOOKUP(B16,Szarvas!$A$123:$AG$245,33,FALSE) -> 3 | G16: 460 | H16: =VLOOKUP(B16,Szarvas!$A$3:$AG$120,33,FALSE) -> 0 | I16: =(E16*F16)+(G16*H16) -> 1140
... A90: 88 | B90: Győri Veronika | C90: =VLOOKUP(B90,Szarvasnévsor!A:C,2,FALSE) -> X2000020 | D90: =VLOOKUP(B90,Szarvasnévsor!A:C,3,FALSE) -> U0000030331 | E90: 380 | F90: =VLOOKUP(B90,Szarvas!$A$123:$AG$245,33,FALSE) -> 5 | G90: 460 | H90: =VLOOKUP(B90,Szarvas!$A$3:$AG$120,33,FALSE) -> 0 | I90: =(E90*F90)+(G90*H90) -> 1900
A91: 89 | B91: =Szarvas!A74 -> Kozák Krisztián | C91: =VLOOKUP(B91,Szarvasnévsor!A:C,2,FALSE) -> X8800205 | D91: =VLOOKUP(B91,Szarvasnévsor!A:C,3,FALSE) -> U0000030332 | E91: 380 | F91: =VLOOKUP(B91,Szarvas!$A$123:$AG$245,33,FALSE) -> 5 | G91: 460 | H91: =VLOOKUP(B91,Szarvas!$A$3:$AG$120,33,FALSE) -> 0 | I91: =(E91*F91)+(G91*H91) -> 1900
A92: 90 | B92: Berkes Sándor | C92: =VLOOKUP(B92,Szarvasnévsor!A:C,2,FALSE) -> X8800205 | D92: =VLOOKUP(B92,Szarvasnévsor!A:C,3,FALSE) -> U0000030332 | E92: 380 | F92: =VLOOKUP(B92,Szarvas!$A$123:$AG$245,33,FALSE) -> 14 | G92: 460 | H92: =VLOOKUP(B92,Szarvas!$A$3:$AG$120,33,FALSE) -> 0 | I92: =(E92*F92)+(G92*H92) -> 5320
A93: 91 | B93: Ujhelyi Beáta | C93: =VLOOKUP(B93,Szarvasnévsor!A:C,2,FALSE) -> X8800205 | D93: =VLOOKUP(B93,Szarvasnévsor!A:C,3,FALSE) -> U0000030332 | E93: 380 | F93: =VLOOKUP(B93,Szarvas!$A$123:$AG$245,33,FALSE) -> 5 | G93: 460 | H93: =VLOOKUP(B93,Szarvas!$A$3:$AG$120,33,FALSE) -> 0 | I93: =(E93*F93)+(G93*H93) -> 1900
A94: 92 | B94: Hadadiné Faragó Erika | C94: =VLOOKUP(B94,Szarvasnévsor!A:C,2,FALSE) -> X2000020 | D94: =VLOOKUP(B94,Szarvasnévsor!A:C,3,FALSE) -> U0000030331 | E94: 380 | F94: =VLOOKUP(B94,Szarvas!$A$123:$AG$245,33,FALSE) -> 17 | G94: 460 | H94: =VLOOKUP(B94,Szarvas!$A$3:$AG$120,33,FALSE) -> 3 | I94: =(E94*F94)+(G94*H94) -> 7840
A95: 93 | B95: Lestyan Mihály | C95: =VLOOKUP(B95,Szarvasnévsor!A:C,2,FALSE) -> X2000020 | D95: =VLOOKUP(B95,Szarvasnévsor!A:C,3,FALSE) -> U0000030331 | E95: 380 | F95: =VLOOKUP(B95,Szarvas!$A$123:$AG$245,33,FALSE) -> 13 | G95: 460 | H95: =VLOOKUP(B95,Szarvas!$A$3:$AG$121,33,FALSE) -> 0 | I95: =(E95*F95)+(G95*H95) -> 4940
A96: 94 | B96: Körmendi János | C96: =VLOOKUP(B96,Szarvasnévsor!A:C,2,FALSE) -> X2000029 | D96: =VLOOKUP(B96,Szarvasnévsor!A:C,3,FALSE) -> U0000030332 | E96: 380 | F96: =VLOOKUP(B96,Szarvas!$A$123:$AG$245,33,FALSE) -> 15 | G96: 460 | H96: =VLOOKUP(B96,Szarvas!$A$3:$AG$121,33,FALSE) -> 0 | I96: =(E96*F96)+(G96*H96) -> 5700
A97: 95 | B97: Csecskediné H. Ágnes | C97: =VLOOKUP(B97,Szarvasnévsor!A:C,2,FALSE) -> X8800205 | D97: =VLOOKUP(B97,Szarvasnévsor!A:C,3,FALSE) -> U0000030332 | E97: 380 | F97: =VLOOKUP(B97,Szarvas!$A$123:$AG$245,33,FALSE) -> 1 | G97: 460 | H97: =VLOOKUP(B97,Szarvas!$A$3:$AG$121,33,FALSE) -> 0 | I97: =(E97*F97)+(G97*H97) -> 380
A98: 96 | B98: Szűcs Erika | C98: =VLOOKUP(B98,Szarvasnévsor!A:C,2,FALSE) -> X2000020 | D98: =VLOOKUP(B98,Szarvasnévsor!A:C,3,FALSE) -> U0000030331 | E98: 380 | F98: =VLOOKUP(B98,Szarvas!$A$123:$AG$245,33,FALSE) -> 17 | G98: 460 | H98: =VLOOKUP(B98,Szarvas!$A$3:$AG$121,33,FALSE) -> 0 | I98: =(E98*F98)+(G98*H98) -> 6460
A99: 97 | B99: Borgulya Szilvia | C99: =VLOOKUP(B99,Szarvasnévsor!A:C,2,FALSE) -> X2000020 | D99: =VLOOKUP(B99,Szarvasnévsor!A:C,3,FALSE) -> U0000030331 | E99: 380 | F99: =VLOOKUP(B99,Szarvas!$A$123:$AG$245,33,FALSE) -> 3 | G99: 460 | H99: =VLOOKUP(B99,Szarvas!$A$3:$AG$121,33,FALSE) -> 0 | I99: =(E99*F99)+(G99*H99) -> 1140
A100: 98 | B100: Nyékiné Laurik Edina | C100: =VLOOKUP(B100,Szarvasnévsor!A:C,2,FALSE) -> X8800205 | D100: =VLOOKUP(B100,Szarvasnévsor!A:C,3,FALSE) -> U0000030332 | E100: 380 | F100: =VLOOKUP(B100,Szarvas!$A$123:$AG$245,33,FALSE) -> 4 | G100: 460 | H100: =VLOOKUP(B100,Szarvas!$A$3:$AG$121,33,FALSE) -> 0 | I100: =(E100*F100)+(G100*H100) -> 1520
A101: 99. | B101: Nagy Éva Erzsébet | C101: =VLOOKUP(B101,Szarvasnévsor!A:C,2,FALSE) -> X2000020 | D101: =VLOOKUP(B101,Szarvasnévsor!A:C,3,FALSE) -> U0000030331 | E101: 380 | F101: =VLOOKUP(B101,Szarvas!$A$123:$AG$245,33,FALSE) -> 17 | G101: 460 | H101: =VLOOKUP(B101,Szarvas!$A$3:$AG$121,33,FALSE) -> 0 | I101: =(E101*F101)+(G101*H101) -> 6460
A102: 100 | B102: Szakál Mihályné | C102: =VLOOKUP(B102,Szarvasnévsor!A:C,2,FALSE) -> X8800205 | D102: =VLOOKUP(B102,Szarvasnévsor!A:C,3,FALSE) -> U0000030332 | E102: 380 | F102: =VLOOKUP(B102,Szarvas!$A$123:$AG$245,33,FALSE) -> 0 | G102: 460 | H102: =VLOOKUP(B102,Szarvas!$A$3:$AG$121,33,FALSE) -> 0 | I102: =(E102*F102)+(G102*H102) -> 0
B103: Összesen | F103: =SUM(F5:F102) -> 526 | H103: =SUM(H5:H102) -> 89 | I103: =SUM(I5:I102) -> 240820
F105: =F103+H103 -> 615
B107: Kelt:Szarvas,2019 október 1. | H107: Készítette:Domján Balázsné

Sheet Középhalom
A1: Nevek | B1: 1 | C1: 2 | D1: 3 | E1: 4 | F1: 5 | G1: 6 | H1: 7 | I1: 8 | J1: 9 | K1: 10 | L1: 11 | M1: 12 | N1: 13 | O1: 14 | P1: 15 | Q1: 16 | R1: 17 | S1: 18 | T1: 19 | U1: 20 | V1: 21 | W1: 22 | X1: 23 | Y1: 24 | Z1: 25 | AA1: 26 | AB1: 27 | AC1: 28 | AD1: 29 | AE1: 30 | AF1: 31 | AG1: Összesen
A2: Dolgozói ebéd(460)
A3: Tanyagondnoki szolgálat
A4: Kozma Tibor | AG4: =SUM(B4:AF4) -> 0
A5: Pásztor Mátyás | AG5: =SUM(B5:AF5) -> 0
A6: Összesen | B6: =SUM(B4:B5) -> 0 | C6: =SUM(C4:C5) -> 0 | D6: =SUM(D4:D5) -> 0 | E6: =SUM(E4:E5) -> 0 | F6: =SUM(F4:F5) -> 0 | G6: =SUM(G4:G5) -> 0 | H6: =SUM(H4:H5) -> 0 | I6: =SUM(I4:I5) -> 0 | ... AG6: =SUM(AG4:AG5) -> 0
A7: Idősek nappli ellátása
A8: Schuszter Zoltánné | AG8: =SUM(B8:AF8) -> 0
A9: Vrbovszkiné Prasz Mária | AG9: =SUM(B9:AF9) -> 0
A10: Összesen | B10: =SUM(B8:B9) -> 0 | C10: =SUM(C8:C9) -> 0 | D10: =SUM(D8:D9) -> 0 | E10: =SUM(E8:E9) -> 0 | F10: =SUM(F8:F9) -> 0 | G10: =SUM(G8:G9) -> 0 | H10: =SUM(H8:H9) -> 0 | I10: =SUM(I8:I9) -> 0 | ... AG10: =SUM(AG8:AG9) -> 0
A13: Tanyagondnoki szolgálat
A14: Kozma Tibor | AG14: =SUM(B14:AF14) -> 0
A15: Pásztor Mátyás | C15: 1 | D15: 1 | E15: 1 | F15: 1 | G15: 1 | H15: 1 | J15: 1 | K15: 1 | L15: 1 | M15: 1 | N15: 1 | O15: 1 | Q15: 1 | R15: 1 | S15: 1 | T15: 1 | U15: 1 | X15: 1 | AE15: 1 | AF15: 1 | AG15: =SUM(B15:AF15) -> 20
A16: Összesen | B16: =SUM(B14:B15) -> 0 | C16: =SUM(C14:C15) -> 1 | D16: =SUM(D14:D15) -> 1 | E16: =SUM(E14:E15) -> 1 | F16: =SUM(F14:F15) -> 1 | G16: =SUM(G14:G15) -> 1 | H16: =SUM(H14:H15) -> 1 | I16: =SUM(I14:I15) -> 0 | ... N16: =SUM(N14:N15) -> 1 | P16: =SUM(P14:P15) -> 0 | Q16: =SUM(Q14:Q15) -> 1 | R16: =SUM(R14:R15) -> 1 | S16: =SUM(S14:S15) -> 1 | T16: =SUM(T14:T15) -> 1 | U16: =SUM(U14:U15) -> 1 | V16: =SUM(V14:V15) -> 0 | W16: =SUM(W14:W15) -> 0 | ... AG16: =SUM(AG14:AG15) -> 20
A17: Idősek nappli ellátása
A18: Schuszter Zoltánné | AG18: =SUM(B18:AF18) -> 0
A19: Vrbovszkiné Prasz Mária | AG19: =SUM(B19:AF19) -> 0
A20: Összesen | B20: =SUM(B18:B19) -> 0 | C20: =SUM(C18:C19) -> 0 | D20: =SUM(D18:D19) -> 0 | E20: =SUM(E18:E19) -> 0 | F20: =SUM(F18:F19) -> 0 | G20: =SUM(G18:G19) -> 0 | H20: =SUM(H18:H19) -> 0 | I20: =SUM(I18:I19) -> 0 | ... AG20: =SUM(AG18:AG19) -> 0
A21: Napi összesen: | B21: =SUM(B4:B5)+SUM(B8:B9)+SUM(B14:B15)+SUM(B18:B19) -> 0 | C21: =SUM(C4:C5)+SUM(C8:C9)+SUM(C14:C15)+SUM(C18:C19) -> 1 | D21: =SUM(D4:D5)+SUM(D8:D9)+SUM(D14:D15)+SUM(D18:D19) -> 1 | E21: =SUM(E4:E5)+SUM(E8:E9)+SUM(E14:E15)+SUM(E18:E19) -> 1 | F21: =SUM(F4:F5)+SUM(F8:F9)+SUM(F14:F15)+SUM(F18:F19) -> 1 | G21: =SUM(G4:G5)+SUM(G8:G9)+SUM(G14:G15)+SUM(G18:G19) -> 1 | H21: =SUM(H4:H5)+SUM(H8:H9)+SUM(H14:H15)+SUM(H18:H19) -> 1 | I21: =SUM(I4:I5)+SUM(I8:I9)+SUM(I14:I15)+SUM(I18:I19) -> 0 | ... AF21: =SUM(AF4:AF5)+SUM(AF8:AF9)+SUM(AF14:AF15)+SUM(AF18:AF19) -> 1 | AG21: =AG20+AG16+AG10+AG6 -> 20

Sheet Középhalom összesen
A1: Adatszolgáltatás számlázáshoz | H1: Dolgozói Étkeztetés | I1: SZEPTEMBER
A2: Ótemplomi Szeretetszolgálat | H2: Domján Balázsné
A3: Étkeztetésben részesülők. | E3: Kedvezményezett ebéd | G3: Dolgozói ebéd
A4: SSz. | B4: Név | C4: xkód | D4: ukód | E4: Bruttó egységár(Ft) | F4: Adagszám(db) | G4: Bruttó egységár (Ft) | H4: Adagszám (db) | I4: Számlázandó összesen (Ft)
A5: 1. | B5: =Középhalom!A4 -> Kozma Tibor | C5: =VLOOKUP(B5,többinévsor!$A$2:$C$27,2,FALSE) -> X2000032 | D5: =VLOOKUP(B5,többinévsor!$A$2:$C$27,3,FALSE) -> U0000030303 | E5: 380 | F5: =Középhalom!AG14 -> 0 | G5: 460 | H5: =Középhalom!AG4 -> 0 | I5: =(E5*F5)+(G5*H5) -> 0
A6: 2. | B6: =Középhalom!A5 -> Pásztor Mátyás | C6: =VLOOKUP(B6,többinévsor!$A$2:$C$27,2,FALSE) -> X2000032 | D6: =VLOOKUP(B6,többinévsor!$A$2:$C$27,3,FALSE) -> U0000030303 | E6: 380 | F6: =Középhalom!AG15 -> 20 | G6: 460 | H6: =Középhalom!AG5 -> 0 | I6: =(E6*F6)+(G6*H6) -> 7600
A7: 3. | B7: =Középhalom!A8 -> Schuszter Zoltánné | C7: =VLOOKUP(B7,többinévsor!$A$2:$C$27,2,FALSE) -> X2000006 | D7: =VLOOKUP(B7,többinévsor!$A$2:$C$27,3,FALSE) -> U0000030303 | E7: 380 | F7: =Középhalom!AG18 -> 0 | G7: 460 | H7: =Középhalom!AG8 -> 0 | I7: =(E7*F7)+(G7*H7) -> 0
A8: 4. | B8: =Középhalom!A9 -> Vrbovszkiné Prasz Mária | C8: =VLOOKUP(B8,többinévsor!$A$2:$C$27,2,FALSE) -> X2000006 | D8: =VLOOKUP(B8,többinévsor!$A$2:$C$27,3,FALSE) -> U0000030303 | E8: 380 | F8: =Középhalom!AG19 -> 0 | G8: 460 | H8: =Középhalom!AG9 -> 0 | I8: =(E8*F8)+(G8*H8) -> 0
B9: Összesen | F9: =SUM(F5:F8) -> 20 | H9: =SUM(H5:H8) -> 0 | I9: =SUM(I5:I8) -> 7600
B13: Kelt:Szarvas,2019 október 1. | H13: Készítette:Domján Balázsné

Sheet Szent László
A1: Nevek | B1: 1 | C1: 2 | D1: 3 | E1: 4 | F1: 5 | G1: 6 | H1: 7 | I1: 8 | J1: 9 | K1: 10 | L1: 11 | M1: 12 | N1: 13 | O1: 14 | P1: 15 | Q1: 16 | R1: 17 | S1: 18 | T1: 19 | U1: 20 | V1: 21 | W1: 22 | X1: 23 | Y1: 24 | Z1: 25 | AA1: 26 | AB1: 27 | AC1: 28 | AD1: 29 | AE1: 30 | AF1: 31 | AG1: Összesen
A2: Dolgozói ebéd(460)
A3: Szent László
A4: Megyik Attila | AG4: =SUM(B4:AF4) -> 0
A5: Jónás Jánosné | AG5: =SUM(B5:AF5) -> 0
A6: Összesen | B6: =SUM(B4:B5) -> 0 | C6: =SUM(C4:C5) -> 0 | D6: =SUM(D4:D5) -> 0 | E6: =SUM(E4:E5) -> 0 | F6: =SUM(F4:F5) -> 0 | G6: =SUM(G4:G5) -> 0 | H6: =SUM(H4:H5) -> 0 | I6: =SUM(I4:I5) -> 0 | ... AG6: =SUM(AG4:AG5) -> 0
A7: Dolgozói ebéd(380)
A8: Szent László
A9: =A4 -> Megyik Attila | C9: 1 | D9: 1 | E9: 1 | G9: 1 | H9: 1 | K9: 1 | L9: 1 | M9: 1 | N9: 1 | O9: 1 | S9: 1 | T9: 1 | AG9: =SUM(B9:AF9) -> 12
A10: =A5 -> Jónás Jánosné | C10: 1 | D10: 1 | E10: 1 | F10: 1 | G10: 1 | H10: 1 | J10: 1 | K10: 1 | L10: 1 | M10: 1 | N10: 1 | O10: 1 | Q10: 1 | R10: 1 | S10: 1 | T10: 1 | U10: 1 | AG10: =SUM(B10:AF10) -> 17
A11: Összesen | B11: =SUM(B9:B10) -> 0 | C11: =SUM(C9:C10) -> 2 | D11: =SUM(D9:D10) -> 2 | E11: =SUM(E9:E10) -> 2 | F11: =SUM(F9:F10) -> 1 | G11: =SUM(G9:G10) -> 2 | H11: =SUM(H9:H10) -> 2 | I11: =SUM(I9:I10) -> 0 | ... AB11: =SUM(AB9:AB10) -> 0 | AD11: =SUM(AD9:AD10) -> 0 | AE11: =SUM(AE9:AE10) -> 0 | AF11: =SUM(AF9:AF10) -> 0 | AG11: =SUM(AG9:AG10) -> 29
A12: Napi összesen: | B12: =SUM(B6,B11) -> 0 | C12: =SUM(C6,C11) -> 2 | D12: =SUM(D6,D11) -> 2 | E12: =SUM(E6,E11) -> 2 | F12: =SUM(F6,F11) -> 1 | G12: =SUM(G6,G11) -> 2 | H12: =SUM(H6,H11) -> 2 | I12: =SUM(I6,I11) -> 0 | ... AF12: =SUM(AF6,AF11) -> 0 | AG12: =AG11+AG6 -> 29
AK17: 5

Sheet Szent László összesen
A1: Adatszolgáltatás számlázáshoz | H1: Dolgozói Étkeztetés | I1: SZEPTEMBER
A2: Ótemplomi Szeretetszolgálat | H2: Domján Balázsné
A3: Étkeztetésben részesülők. | E3: Kedvezményezett ebéd | G3: Dolgozói ebéd
A4: SSz. | B4: Név | C4: xkód | D4: ukód | E4: Bruttó egységár(Ft) | F4: Adagszám(db) | G4: Bruttó egységár (Ft) | H4: Adagszám (db) | I4: Számlázandó összesen (Ft)
A5: 1. | B5: ='Szent László'!A4 -> Megyik Attila | C5: =VLOOKUP(B5,többinévsor!$A$2:$C$27,2,FALSE) -> X2000050 | D5: =VLOOKUP(B5,többinévsor!$A$2:$C$27,3,FALSE) -> U0000030305 | E5: 380 | F5: ='Szent László'!AG9 -> 12 | G5: 460 | H5: ='Szent László'!AG4 -> 0 | I5: =(E5*F5)+(G5*H5) -> 4560
A6: 2. | B6: ='Szent László'!A5 -> Jónás Jánosné | C6: =VLOOKUP(B6,többinévsor!$A$2:$C$27,2,FALSE) -> X2000050 | D6: =VLOOKUP(B6,többinévsor!$A$2:$C$27,3,FALSE) -> U0000030305 | E6: 380 | F6: ='Szent László'!AG10 -> 17 | G6: 460 | H6: ='Szent László'!AG5 -> 0 | I6: =(E6*F6)+(G6*H6) -> 6460
B7: Összesen | F7: =SUM(F5:F6) -> 29 | H7: =SUM(H5:H6) -> 0 | I7: =SUM(I5:I6) -> 11020
B11: Kelt:Szarvas,2019 október 1. | H11: Készítette:Domján Balázsné

Sheet Csabacsűd
A1: Nevek | B1: 1 | C1: 2 | D1: 3 | E1: 4 | F1: 5 | G1: 6 | H1: 7 | I1: 8 | J1: 9 | K1: 10 | L1: 11 | M1: 12 | N1: 13 | O1: 14 | P1: 15 | Q1: 16 | R1: 17 | S1: 18 | T1: 19 | U1: 20 | V1: 21 | W1: 22 | X1: 23 | Y1: 24 | Z1: 25 | AA1: 26 | AB1: 27 | AC1: 28 | AD1: 29 | AE1: 30 | AF1: 31 | AG1: Összesen
A2: Dolgozói ebéd(460)
A3: Csabacsűd
A4: Fábri Györgyné | AG4: =SUM(B4:AF4) -> 0
A5: Fazakasné Halizczki Judit | AG5: =SUM(B5:AF5) -> 0
A6: Hudákné Juhos Mária | AG6: =SUM(B6:AF6) -> 0
A7: Katona Sándorné | AG7: =SUM(B7:AF7) -> 0
A8: Kovácsné Molnár Katalin | AG8: =SUM(B8:AF8) -> 0
A9: Lipták Jánosné | AG9: =SUM(B9:AF9) -> 0
A10: Medvegyné Babarik Erika | AG10: =SUM(B10:AF10) -> 0
A11: Nemesváriné Papp Katalin | AG11: =SUM(B11:AF11) -> 0
A12: Pálfiné Török Eszter | AG12: =SUM(B12:AF12) -> 0
A13: Sepeczán Erzsébet | AG13: =SUM(B13:AF13) -> 0
A14: Szilágyi Ildikó | AG14: =SUM(B14:AF14) -> 0
A15: Szurdiné Birkás Éva | AG15: =SUM(B15:AF15) -> 0
A16: Tóth Mihályné | AG16: =SUM(B16:AF16) -> 0
A17: Összesen | B17: =SUM(B4:B16) -> 0 | C17: =SUM(C4:C16) -> 0 | D17: =SUM(D4:D16) -> 0 | E17: =SUM(E4:E16) -> 0 | F17: =SUM(F4:F16) -> 0 | G17: =SUM(G4:G16) -> 0 | H17: =SUM(H4:H16) -> 0 | I17: =SUM(I4:I16) -> 0 | ... AG17: =SUM(AG4:AG16) -> 0
A19: Dolgozói ebéd(380)
A20: Csabacsűd
A21: =A4 -> Fábri Györgyné | AG21: =SUM(B21:AF21) -> 0
A22: =A5 -> Fazakasné Halizczki Judit | AG22: =SUM(B22:AF22) -> 0
A23: =A6 -> Hudákné Juhos Mária | AG23: =SUM(B23:AF23) -> 0
A24: =A7 -> Katona Sándorné | AG24: =SUM(B24:AF24) -> 0
A25: =A8 -> Kovácsné Molnár Katalin | AG25: =SUM(B25:AF25) -> 0
A26: =A9 -> Lipták Jánosné | AG26: =SUM(B26:AF26) -> 0
A27: =A10 -> Medvegyné Babarik Erika | AG27: =SUM(B27:AF27) -> 0
A28: =A11 -> Nemesváriné Papp Katalin | AG28: =SUM(B28:AF28) -> 0
A29: =A12 -> Pálfiné Török Eszter | AG29: =SUM(B29:AF29) -> 0
A30: =A13 -> Sepeczán Erzsébet | AG30: =SUM(B30:AF30) -> 0
A31: =A14 -> Szilágyi Ildikó | AG31: =SUM(B31:AF31) -> 0
A32: =A15 -> Szurdiné Birkás Éva | AG32: =SUM(B32:AF32) -> 0
A33: =A16 -> Tóth Mihályné | AG33: =SUM(B33:AF33) -> 0
A34: Összesen | B34: =SUM(B21:B33) -> 0 | C34: =SUM(C21:C33) -> 0 | D34: =SUM(D21:D33) -> 0 | E34: =SUM(E21:E33) -> 0 | F34: =SUM(F21:F33) -> 0 | G34: =SUM(G21:G33) -> 0 | H34: =SUM(H21:H33) -> 0 | I34: =SUM(I21:I33) -> 0 | ... AG34: =SUM(AG21:AG33) -> 0
A35: Napi összesen: | B35: =SUM(B17,B34) -> 0 | C35: =SUM(C17,C34) -> 0 | D35: =SUM(D17,D34) -> 0 | E35: =SUM(E17,E34) -> 0 | F35: =SUM(F17,F34) -> 0 | G35: =SUM(G17,G34) -> 0 | H35: =SUM(H17,H34) -> 0 | I35: =SUM(I17,I34) -> 0 | ... AF35: =SUM(AF17,AF34) -> 0

Sheet Csabacsűd összesen
A1: Adatszolgáltatás számlázáshoz | H1: Dolgozói Étkeztetés | I1: JÚNIUS
A2: Ótemplomi Szeretetszolgálat | H2: Domján Balázsné
A3: Étkeztetésben részesülők. | E3: Kedvezményezett ebéd | G3: Dolgozói ebéd
A4: SSz. | B4: Név | C4: xkód | D4: ukód | E4: Bruttó egységár(Ft) | F4: Adagszám(db) | G4: Bruttó egységár (Ft) | H4: Adagszám (db) | I4: Számlázandó összesen (Ft)
A5: 1. | B5: =Csabacsűd!A4 -> Fábri Györgyné | C5: =VLOOKUP(B5,többinévsor!$A$2:$C$27,2,FALSE) -> X2000020 | D5: =VLOOKUP(B5,többinévsor!$A$2:$C$27,3,FALSE) -> U0000030321 | E5: 380 | F5: =Csabacsűd!AG21 -> 0 | G5: 460 | H5: =Csabacsűd!AG4 -> 0 | I5: =(E5*F5)+(G5*H5) -> 0
A6: 2. | B6: =Csabacsűd!A5 -> Fazakasné Halizczki Judit | C6: =VLOOKUP(B6,többinévsor!$A$2:$C$27,2,FALSE) -> X2000020 | D6: =VLOOKUP(B6,többinévsor!$A$2:$C$27,3,FALSE) -> U0000030321 | E6: 380 | F6: =Csabacsűd!AG22 -> 0 | G6: 460 | H6: =Csabacsűd!AG5 -> 0 | I6: =(E6*F6)+(G6*H6) -> 0
A7: 3. | B7: =Csabacsűd!A6 -> Hudákné Juhos Mária | C7: =VLOOKUP(B7,többinévsor!$A$2:$C$27,2,FALSE) -> X2000020 | D7: =VLOOKUP(B7,többinévsor!$A$2:$C$27,3,FALSE) -> U0000030321 | E7: 380 | F7: =Csabacsűd!AG23 -> 0 | G7: 460 | H7: =Csabacsűd!AG6 -> 0 | I7: =(E7*F7)+(G7*H7) -> 0
A8: 4. | B8: =Csabacsűd!A7 -> Katona Sándorné | C8: =VLOOKUP(B8,többinévsor!$A$2:$C$27,2,FALSE) -> X2000020 | D8: =VLOOKUP(B8,többinévsor!$A$2:$C$27,3,FALSE) -> U0000030321 | E8: 380 | F8: =Csabacsűd!AG24 -> 0 | G8: 460 | H8: =Csabacsűd!AG7 -> 0 | I8: =(E8*F8)+(G8*H8) -> 0
A9: 5. | B9: =Csabacsűd!A8 -> Kovácsné Molnár Katalin | C9: =VLOOKUP(B9,többinévsor!$A$2:$C$27,2,FALSE) -> X2000020 | D9: =VLOOKUP(B9,többinévsor!$A$2:$C$27,3,FALSE) -> U0000030321 | E9: 380 | F9: =Csabacsűd!AG25 -> 0 | G9: 460 | H9: =Csabacsűd!AG8 -> 0 | I9: =(E9*F9)+(G9*H9) -> 0
A10: 7. | B10: =Csabacsűd!A9 -> Lipták Jánosné | C10: =VLOOKUP(B10,többinévsor!$A$2:$C$27,2,FALSE) -> X2000020 | D10: =VLOOKUP(B10,többinévsor!$A$2:$C$27,3,FALSE) -> U0000030321 | E10: 380 | F10: =Csabacsűd!AG26 -> 0 | G10: 460 | H10: =Csabacsűd!AG9 -> 0 | I10: =(E10*F10)+(G10*H10) -> 0
A11: 8. | B11: =Csabacsűd!A10 -> Medvegyné Babarik Erika | C11: =VLOOKUP(B11,többinévsor!$A$2:$C$27,2,FALSE) -> X2000020 | D11: =VLOOKUP(B11,többinévsor!$A$2:$C$27,3,FALSE) -> U0000030321 | E11: 380 | F11: =Csabacsűd!AG27 -> 0 | G11: 460 | H11: =Csabacsűd!AG10 -> 0 | I11: =(E11*F11)+(G11*H11) -> 0
A12: 9. | B12: =Csabacsűd!A11 -> Nemesváriné Papp Katalin | C12: =VLOOKUP(B12,többinévsor!$A$2:$C$27,2,FALSE) -> X2000020 | D12: =VLOOKUP(B12,többinévsor!$A$2:$C$27,3,FALSE) -> U0000030321 | E12: 380 | F12: =Csabacsűd!AG28 -> 0 | G12: 460 | H12: =Csabacsűd!AG11 -> 0 | I12: =(E12*F12)+(G12*H12) -> 0
A13: 10. | B13: =Csabacsűd!A12 -> Pálfiné Török Eszter | C13: =VLOOKUP(B13,többinévsor!$A$2:$C$27,2,FALSE) -> X2000020 | D13: =VLOOKUP(B13,többinévsor!$A$2:$C$27,3,FALSE) -> U0000030321 | E13: 380 | F13: =Csabacsűd!AG29 -> 0 | G13: 460 | H13: =Csabacsűd!AG12 -> 0 | I13: =(E13*F13)+(G13*H13) -> 0
A14: 12. | B14: =Csabacsűd!A13 -> Sepeczán Erzsébet | C14: =VLOOKUP(B14,többinévsor!$A$2:$C$27,2,FALSE) -> X2000020 | D14: =VLOOKUP(B14,többinévsor!$A$2:$C$27,3,FALSE) -> U0000030321 | E14: 380 | F14: =Csabacsűd!AG30 -> 0 | G14: 460 | H14: =Csabacsűd!AG13 -> 0 | I14: =(E14*F14)+(G14*H14) -> 0
A15: 13. | B15: =Csabacsűd!A14 -> Szilágyi Ildikó | C15: =VLOOKUP(B15,többinévsor!$A$2:$C$27,2,FALSE) -> X2000020 | D15: =VLOOKUP(B15,többinévsor!$A$2:$C$27,3,FALSE) -> U0000030321 | E15: 380 | F15: =Csabacsűd!AG31 -> 0 | G15: 460 | H15: =Csabacsűd!AG14 -> 0 | I15: =(E15*F15)+(G15*H15) -> 0
A16: 14. | B16: =Csabacsűd!A15 -> Szurdiné Birkás Éva | C16: =VLOOKUP(B16,többinévsor!$A$2:$C$27,2,FALSE) -> X2000020 | D16: =VLOOKUP(B16,többinévsor!$A$2:$C$27,3,FALSE) -> U0000030321 | E16: 380 | F16: =Csabacsűd!AG32 -> 0 | G16: 460 | H16: =Csabacsűd!AG15 -> 0 | I16: =(E16*F16)+(G16*H16) -> 0
A17: 15. | B17: =Csabacsűd!A16 -> Tóth Mihályné | C17: =VLOOKUP(B17,többinévsor!$A$2:$C$27,2,FALSE) -> X2000020 | D17: =VLOOKUP(B17,többinévsor!$A$2:$C$27,3,FALSE) -> U0000030321 | E17: 380 | F17: =Csabacsűd!AG33 -> 0 | G17: 460 | H17: =Csabacsűd!AG16 -> 0 | I17: =(E17*F17)+(G17*H17) -> 0
B18: Összesen | F18: =SUM(F5:F17) -> 0 | H18: =SUM(H5:H17) -> 0 | I18: =SUM(I5:I17) -> 0
B22: Kelt:Szarvas,2018 május 31. | H22: Készítette:Domján Balázsné

Sheet Örménykút
A1: Nevek | B1: 1 | C1: 2 | D1: 3 | E1: 4 | F1: 5 | G1: 6 | H1: 7 | I1: 8 | J1: 9 | K1: 10 | L1: 11 | M1: 12 | N1: 13 | O1: 14 | P1: 15 | Q1: 16 | R1: 17 | S1: 18 | T1: 19 | U1: 20 | V1: 21 | W1: 22 | X1: 23 | Y1: 24 | Z1: 25 | AA1: 26 | AB1: 27 | AC1: 28 | AD1: 29 | AE1: 30 | AF1: 31 | AG1: Összesen
A2: Dolgozói ebéd(460)
A3: Házisegítség nyújtás
A4: Kisné Galáth Annamária | AG4: =SUM(B4:AF4) -> 0
A5: Molnár Györgyné | AG5: =SUM(B5:AF5) -> 0
A6: Breznyik Zsuzsanna | AG6: =SUM(B6:AF6) -> 0
A7: Összesen | B7: =SUM(B4:B6) -> 0 | C7: =SUM(C4:C6) -> 0 | D7: =SUM(D4:D6) -> 0 | E7: =SUM(E4:E6) -> 0 | F7: =SUM(F4:F6) -> 0 | G7: =SUM(G4:G6) -> 0 | H7: =SUM(H4:H6) -> 0 | I7: =SUM(I4:I6) -> 0 | ... AG7: =SUM(AG4:AG6) -> 0
A8: Idősek Nappali Ellátás
A9: Ipsitsné Gergely Anna | AG9: =SUM(B9:AF9) -> 0
AG10: =SUM(B10:AF10) -> 0
AG11: =SUM(B11:AF11) -> 0
A12: Összesen | B12: =SUM(B9:B11) -> 0 | C12: =SUM(C9:C11) -> 0 | D12: =SUM(D9:D11) -> 0 | E12: =SUM(E9:E11) -> 0 | F12: =SUM(F9:F11) -> 0 | G12: =SUM(G9:G11) -> 0 | H12: =SUM(H9:H11) -> 0 | I12: =SUM(I9:I11) -> 0 | ... AG12: =SUM(AG9:AG11) -> 0
A14: Dolgozói ebéd(380)
A15: Házisegítség nyújtás
A16: =A4 -> Kisné Galáth Annamária | AG16: =SUM(B16:AF16) -> 0
A17: =A5 -> Molnár Györgyné | C17: 1 | D17: 1 | E17: 1 | F17: 1 | G17: 1 | H17: 1 | J17: 1 | K17: 1 | L17: 1 | M17: 1 | N17: 1 | O17: 1 | Q17: 1 | R17: 1 | S17: 1 | T17: 1 | U17: 1 | X17: 1 | AE17: 1 | AF17: 1 | AG17: =SUM(B17:AF17) -> 20
A18: =A6 -> Breznyik Zsuzsanna | AG18: =SUM(B18:AF18) -> 0
A19: Összesen | B19: =SUM(B16:B18) -> 0 | C19: =SUM(C16:C18) -> 1 | D19: =SUM(D16:D18) -> 1 | E19: =SUM(E16:E18) -> 1 | F19: =SUM(F16:F18) -> 1 | G19: =SUM(G16:G18) -> 1 | I19: =SUM(I16:I18) -> 0 | J19: =SUM(J16:J18) -> 1 | K19: =SUM(K16:K18) -> 1 | L19: =SUM(L16:L18) -> 1 | M19: =SUM(M16:M18) -> 1 | N19: =SUM(N16:N18) -> 1 | O19: =SUM(O16:O18) -> 1 | P19: =SUM(P16:P18) -> 0 | ... AG19: =SUM(AG16:AG18) -> 20
A20: Idősek Nappali Ellátás
A21: =A9 -> Ipsitsné Gergely Anna | C21: 1 | D21: 1 | E21: 1 | F21: 1 | G21: 1 | H21: 1 | J21: 1 | K21: 1 | L21: 1 | M21: 1 | N21: 1 | O21: 1 | Q21: 1 | R21: 1 | S21: 1 | T21: 1 | U21: 1 | X21: 1 | AE21: 1 | AF21: 1 | AG21: =SUM(B21:AF21) -> 20
A22: =A10 -> 0 | AG22: =SUM(B22:AF22) -> 0
A23: =A11 -> 0 | AG23: =SUM(B23:AF23) -> 0
A24: Összesen | B24: =SUM(B21:B23) -> 0 | C24: =SUM(C21:C23) -> 1 | D24: =SUM(D21:D23) -> 1 | E24: =SUM(E21:E23) -> 1 | F24: =SUM(F21:F23) -> 1 | G24: =SUM(G21:G23) -> 1 | H24: =SUM(H21:H23) -> 1 | I24: =SUM(I21:I23) -> 0 | ... AG24: =SUM(AG21:AG23) -> 20
A25: Napi összesen: | B25: =SUM(B21:B23)+ SUM(B16:B18)+SUM(B9:B11)+SUM(B4:B6) -> 0 | C25: =SUM(C21:C23)+ SUM(C16:C18)+SUM(C9:C11)+SUM(C4:C6) -> 2 | D25: =SUM(D21:D23)+ SUM(D16:D18)+SUM(D9:D11)+SUM(D4:D6) -> 2 | E25: =SUM(E21:E23)+ SUM(E16:E18)+SUM(E9:E11)+SUM(E4:E6) -> 2 | F25: =SUM(F21:F23)+ SUM(F16:F18)+SUM(F9:F11)+SUM(F4:F6) -> 2 | G25: =SUM(G21:G23)+ SUM(G16:G18)+SUM(G9:G11)+SUM(G4:G6) -> 2 | H25: =SUM(H21:H23)+ SUM(H16:H18)+SUM(H9:H11)+SUM(H4:H6) -> 2 | I25: =SUM(I21:I23)+ SUM(I16:I18)+SUM(I9:I11)+SUM(I4:I6) -> 0 | ... AF25: =SUM(AF21:AF23)+ SUM(AF16:AF18)+SUM(AF9:AF11)+SUM(AF4:AF6) -> 2 | AG25: =AG24+AG19 -> 40

Sheet Örménykút összesen
A1: Adatszolgáltatás számlázáshoz | H1: Dolgozói Étkeztetés | I1: SZEPTEMBER
A2: Ótemplomi Szeretetszolgálat | H2: Domján Balázsné
A3: Étkeztetésben részesülők. | E3: Kedvezményezett ebéd | G3: Dolgozói ebéd
A4: SSz. | B4: Név | C4: xkód | D4: ukód | E4: Bruttó egységár(Ft) | F4: Adagszám(db) | G4: Bruttó egységár (Ft) | H4: Adagszám (db) | I4: Számlázandó összesen (Ft)
A5: 1. | B5: =Örménykút!A4 -> Kisné Galáth Annamária | C5: =VLOOKUP(B5,többinévsor!$A$2:$C$27,2,FALSE) -> X2000005 | D5: =VLOOKUP(B5,többinévsor!$A$2:$C$27,3,FALSE) -> U0000030302 | E5: 380 | F5: =Örménykút!AG16 -> 0 | G5: 460 | H5: =Örménykút!AG4 -> 0 | I5: =(E5*F5)+(G5*H5) -> 0
A6: 2. | B6: =Örménykút!A5 -> Molnár Györgyné | C6: =VLOOKUP(B6,többinévsor!$A$2:$C$27,2,FALSE) -> X2000005 | D6: =VLOOKUP(B6,többinévsor!$A$2:$C$27,3,FALSE) -> U0000030302 | E6: 380 | F6: =Örménykút!AG17 -> 20 | G6: 460 | H6: =Örménykút!AG5 -> 0 | I6: =(E6*F6)+(G6*H6) -> 7600
A7: 3. | B7: =Örménykút!A6 -> Breznyik Zsuzsanna | C7: =VLOOKUP(B7,többinévsor!$A$2:$C$27,2,FALSE) -> X2000005 | D7: =VLOOKUP(B7,többinévsor!$A$2:$C$27,3,FALSE) -> U0000030302 | E7: 380 | F7: =Örménykút!AG18 -> 0 | G7: 460 | H7: =Örménykút!AG6 -> 0 | I7: =(E7*F7)+(G7*H7) -> 0
A8: 4. | B8: =Örménykút!A9 -> Ipsitsné Gergely Anna | C8: =VLOOKUP(B8,többinévsor!$A$2:$C$27,2,FALSE) -> X2000006 | D8: =VLOOKUP(B8,többinévsor!$A$2:$C$27,3,FALSE) -> U0000030302 | E8: 380 | F8: =Örménykút!AG21 -> 20 | G8: 460 | H8: =Örménykút!AG9 -> 0 | I8: =(E8*F8)+(G8*H8) -> 7600
A9: 20. | B9: =Örménykút!A10 -> 0 | C9: =VLOOKUP(B9,többinévsor!$A$2:$C$27,2,FALSE) -> #N/A | D9: =VLOOKUP(B9,többinévsor!$A$2:$C$27,3,FALSE) -> #N/A | E9: 380 | F9: =Örménykút!AG22 -> 0 | G9: 460 | H9: =Örménykút!AG10 -> 0 | I9: =(E9*F9)+(G9*H9) -> 0
B10: Összesen | F10: =SUM(F5:F9) -> 40 | H10: =SUM(H5:H9) -> 0 | I10: =SUM(I5:I9) -> 15200
B14: Kelt:Szarvas,2019 október 01. | H14: Készítette:Domján Balázsné

Sheet Vajda
A1: Nevek | B1: 1 | C1: 2 | D1: 3 | E1: 4 | F1: 5 | G1: 6 | H1: 7 | I1: 8 | J1: 9 | K1: 10 | L1: 11 | M1: 12 | N1: 13 | O1: 14 | P1: 15 | Q1: 16 | R1: 17 | S1: 18 | T1: 19 | U1: 20 | V1: 21 | W1: 22 | X1: 23 | Y1: 24 | Z1: 25 | AA1: 26 | AB1: 27 | AC1: 28 | AD1: 29 | AE1: 30 | AF1: 31 | AG1: Összesen
A2: Dolgozói ebéd(460)
A3: Szenv.közösségi ellát.(Tessedik)(460)
A4: Láng Emese | AG4: =SUM(B4:AF4) -> 0
A5: Galó Tamás | AG5: =SUM(B5:AF5) -> 0
A6: Molnár Pál | AG6: =SUM(B6:AF6) -> 0
A7: Összesen | B7: =SUM(B4:B6) -> 0 | C7: =SUM(C4:C6) -> 0 | D7: =SUM(D4:D6) -> 0 | E7: =SUM(E4:E6) -> 0 | F7: =SUM(F4:F6) -> 0 | G7: =SUM(G4:G6) -> 0 | H7: =SUM(H4:H6) -> 0 | I7: =SUM(I4:I6) -> 0 | ... AG7: =SUM(AG4:AG6) -> 0
A8: Jelzőr.házi segítsny(460)
A9: Csire Melinda | AG9: =SUM(B9:AF9) -> 0
A10: Összesen | B10: =SUM(B9) -> 0 | C10: =SUM(C9) -> 0 | D10: =SUM(D9) -> 0 | E10: =SUM(E9) -> 0 | F10: =SUM(F9) -> 0 | G10: =SUM(G9) -> 0 | H10: =SUM(H9) -> 0 | I10: =SUM(I9) -> 0 | ... AG10: =SUM(AG9) -> 0
A11: Otthoni szakápolás(460)
A12: Fülepi Aranka | AG12: =SUM(B12:AF12) -> 0
A13: Összesen | B13: =SUM(B12) -> 0 | C13: =SUM(C12) -> 0 | D13: =SUM(D12) -> 0 | E13: =SUM(E12) -> 0 | F13: =SUM(F12) -> 0 | G13: =SUM(G12) -> 0 | H13: =SUM(H12) -> 0 | I13: =SUM(I12) -> 0 | ... AG13: =SUM(AG12) -> 0
A14: Szociális Étkeztetés(460)
A15: Pribelszki András | AG15: =SUM(B15:AF15) -> 0
A16: Kelemen Márta | AG16: =SUM(B16:AF16) -> 0
A17: Valyó András | AG17: =SUM(B17:AF17) -> 0
A18: Demcsákné Rafaj Veronika | AG18: =SUM(B18:AF18) -> 0
A19: Skorka Kitti | AG19: =SUM(B19:AF19) -> 0
A20: Cseri Ildikó | AG20: =SUM(B20:AF20) -> 0
A21: Himmer Péter | B21: 1 | C21: 1 | D21: 1 | E21: 1 | F21: 1 | G21: 1 | H21: 1 | I21: 1 | J21: 1 | L21: 1 | M21: 1 | N21: 1 | O21: 1 | P21: 1 | Q21: 1 | R21: 1 | S21: 1 | T21: 1 | U21: 1 | V21: 1 | W21: 1 | X21: 1 | Y21: 1 | Z21: 1 | AA21: 1 | AB21: 1 | AC21: 1 | AD21: 1 | AE21: 1 | AF21: 1 | AG21: =SUM(B21:AF21) -> 30
AG22: =SUM(B22:AF22) -> 0
AG23: =SUM(B23:AF23) -> 0
AG24: =SUM(B24:AF24) -> 0
A25: Összesen | B25: =SUM(B15:B24) -> 1 | C25: =SUM(C15:C24) -> 1 | D25: =SUM(D15:D24) -> 1 | E25: =SUM(E15:E24) -> 1 | F25: =SUM(F15:F24) -> 1 | G25: =SUM(G15:G24) -> 1 | H25: =SUM(H15:H24) -> 1 | I25: =SUM(I15:I24) -> 1 | ... AG25: =SUM(AG15:AG24) -> 30
A26: Fogyatékos személyek nappali ellátása(460)
A27: Balatoni Anita | AG27: =SUM(B27:AF27) -> 0
A28: Erdei Sándorné | AG28: =SUM(B28:AF28) -> 0
A29: Gazsó László | AG29: =SUM(B29:AF29) -> 0
A30: Hatvani Károly Józsefné | AG30: =SUM(B30:AF30) -> 0
A31: Molnárné Szappanos Ilona T. | AG31: =SUM(B31:AF31) -> 0
A32: Összesen | B32: =SUM(B27:B31) -> 0 | C32: =SUM(C27:C31) -> 0 | D32: =SUM(D27:D31) -> 0 | E32: =SUM(E27:E31) -> 0 | F32: =SUM(F27:F31) -> 0 | G32: =SUM(G27:G31) -> 0 | H32: =SUM(H27:H31) -> 0 | I32: =SUM(I27:I31) -> 0 | ... AG32: =SUM(AG27:AG31) -> 0
A33: Demens betegek nappali ellátása(460)
A34: Kis Gabriella | AG34: =SUM(B34:AF34) -> 0
A35: Kozsuch Jánosné | AG35: =SUM(B35:AF35) -> 0
A36: Kiszelné Nyemcsok Edit | AG36: =SUM(B36:AF36) -> 0
A37: Krajcsiné Petrov Gabriella | AG37: =SUM(B37:AF37) -> 0
A38: Stancsikné Hruska Judit | AG38: =SUM(B38:AF38) -> 0
A39: Összesen | B39: =SUM(B34:B38) -> 0 | C39: =SUM(C34:C38) -> 0 | D39: =SUM(D34:D38) -> 0 | E39: =SUM(E34:E38) -> 0 | F39: =SUM(F34:F38) -> 0 | G39: =SUM(G34:G38) -> 0 | H39: =SUM(H34:H38) -> 0 | I39: =SUM(I34:I38) -> 0 | ... AG39: =SUM(AG34:AG38) -> 0
A40: Támogató Szolgálat(460)
...

Sheet Vajda összesen
A1: Adatszolgáltatás számlázáshoz | H1: Dolgozói Étkeztetés | I1: SZEPTEMBER
A2: Ótemplomi Szeretetszolgálat | H2: Domján Balázsné
A3: Étkeztetésben részesülők. | E3: Kedvezményezett ebéd | G3: Dolgozói ebéd
A4: SSz. | B4: Név | C4: xkód | D4: ukód | E4: Bruttó egységár(Ft) | F4: Adagszám(db) | G4: Bruttó egységár (Ft) | H4: Adagszám (db) | I4: Számlázandó összesen (Ft)
A5: 1. | B5: =Vajda!A4 -> Láng Emese | C5: =VLOOKUP(B5,Vajdanévsor!$A$2:$C$107,2,FALSE) -> X2000037 | D5: =VLOOKUP(B5,Vajdanévsor!$A$2:$C$107,3,FALSE) -> U0000030301 | E5: 380 | F5: =VLOOKUP(B5,Vajda!$A$125:$AG$242,33,FALSE) -> 0 | G5: 460 | H5: =VLOOKUP(B5,Vajda!$A$3:$AG$121,33,FALSE) -> 0 | I5: =(E5*F5)+(G5*H5) -> 0
A6: 2. | B6: =Vajda!A5 -> Galó Tamás | C6: =VLOOKUP(B6,Vajdanévsor!$A$2:$C$107,2,FALSE) -> X2000037 | D6: =VLOOKUP(B6,Vajdanévsor!$A$2:$C$107,3,FALSE) -> U0000030301 | E6: 380 | F6: =VLOOKUP(B6,Vajda!$A$125:$AG$242,33,FALSE) -> 0 | G6: 460 | H6: =VLOOKUP(B6,Vajda!$A$3:$AG$121,33,FALSE) -> 0 | I6: =(E6*F6)+(G6*H6) -> 0
A7: 3. | B7: =Vajda!A6 -> Molnár Pál | C7: =VLOOKUP(B7,Vajdanévsor!$A$2:$C$107,2,FALSE) -> X2000037 | D7: =VLOOKUP(B7,Vajdanévsor!$A$2:$C$107,3,FALSE) -> U0000030301 | E7: 380 | F7: =VLOOKUP(B7,Vajda!$A$125:$AG$242,33,FALSE) -> 0 | G7: 460 | H7: =VLOOKUP(B7,Vajda!$A$3:$AG$121,33,FALSE) -> 0 | I7: =(E7*F7)+(G7*H7) -> 0
A8: 4. | B8: =Vajda!A9 -> Csire Melinda | C8: =VLOOKUP(B8,Vajdanévsor!$A$2:$C$107,2,FALSE) -> X2000014 | D8: =VLOOKUP(B8,Vajdanévsor!$A$2:$C$107,3,FALSE) -> U0000030301 | E8: 380 | F8: =VLOOKUP(B8,Vajda!$A$125:$AG$242,33,FALSE) -> 0 | G8: 460 | H8: =VLOOKUP(B8,Vajda!$A$3:$AG$121,33,FALSE) -> 0 | I8: =(E8*F8)+(G8*H8) -> 0
A9: 5. | B9: =Vajda!A12 -> Fülepi Aranka | C9: =VLOOKUP(B9,Vajdanévsor!$A$2:$C$107,2,FALSE) -> X2100001 | D9: =VLOOKUP(B9,Vajdanévsor!$A$2:$C$107,3,FALSE) -> U0000030301 | E9: 380 | F9: =VLOOKUP(B9,Vajda!$A$125:$AG$242,33,FALSE) -> 0 | G9: 460 | H9: =VLOOKUP(B9,Vajda!$A$3:$AG$121,33,FALSE) -> 0 | I9: =(E9*F9)+(G9*H9) -> 0
A10: 6. | B10: =Vajda!A15 -> Pribelszki András | C10: =VLOOKUP(B10,Vajdanévsor!$A$2:$C$107,2,FALSE) -> X2000004 | D10: =VLOOKUP(B10,Vajdanévsor!$A$2:$C$107,3,FALSE) -> U0000030301 | E10: 380 | F10: =VLOOKUP(B10,Vajda!$A$125:$AG$242,33,FALSE) -> 17 | G10: 460 | H10: =VLOOKUP(B10,Vajda!$A$3:$AG$121,33,FALSE) -> 0 | I10: =(E10*F10)+(G10*H10) -> 6460
A11: 7. | B11: Kelemen Márta | C11: =VLOOKUP(B11,Vajdanévsor!$A$2:$C$107,2,FALSE) -> X2000004 | D11: =VLOOKUP(B11,Vajdanévsor!$A$2:$C$107,3,FALSE) -> U0000030301 | E11: 380 | F11: =VLOOKUP(B11,Vajda!$A$125:$AG$242,33,FALSE) -> 8 | G11: 460 | H11: =VLOOKUP(B11,Vajda!$A$3:$AG$121,33,FALSE) -> 0 | I11: =(E11*F11)+(G11*H11) -> 3040
A12: 8. | B12: =Vajda!A17 -> Valyó András | C12: =VLOOKUP(B12,Vajdanévsor!$A$2:$C$107,2,FALSE) -> X2000004 | D12: =VLOOKUP(B12,Vajdanévsor!$A$2:$C$107,3,FALSE) -> U0000030301 | E12: 380 | F12: =VLOOKUP(B12,Vajda!$A$125:$AG$242,33,FALSE) -> 0 | G12: 460 | H12: =VLOOKUP(B12,Vajda!$A$3:$AG$121,33,FALSE) -> 0 | I12: =(E12*F12)+(G12*H12) -> 0
A13: 9. | B13: =Vajda!A18 -> Demcsákné Rafaj Veronika | C13: =VLOOKUP(B13,Vajdanévsor!$A$2:$C$107,2,FALSE) -> X2000004 | D13: =VLOOKUP(B13,Vajdanévsor!$A$2:$C$107,3,FALSE) -> U0000030301 | E13: 380 | F13: =VLOOKUP(B13,Vajda!$A$125:$AG$242,33,FALSE) -> 4 | G13: 460 | H13: =VLOOKUP(B13,Vajda!$A$3:$AG$121,33,FALSE) -> 0 | I13: =(E13*F13)+(G13*H13) -> 1520
A14: 10. | B14: =Vajda!A19 -> Skorka Kitti | C14: =VLOOKUP(B14,Vajdanévsor!$A$2:$C$107,2,FALSE) -> X2000004 | D14: =VLOOKUP(B14,Vajdanévsor!$A$2:$C$107,3,FALSE) -> U0000030301 | E14: 380 | F14: =VLOOKUP(B14,Vajda!$A$125:$AG$242,33,FALSE) -> 7 | G14: 460 | H14: =VLOOKUP(B14,Vajda!$A$3:$AG$121,33,FALSE) -> 0 | I14: =(E14*F14)+(G14*H14) -> 2660
A15: 11. | B15: =Vajda!A20 -> Cseri Ildikó | C15: =VLOOKUP(B15,Vajdanévsor!$A$2:$C$107,2,FALSE) -> X2000004 | D15: =VLOOKUP(B15,Vajdanévsor!$A$2:$C$107,3,FALSE) -> U0000030301 | E15: 380 | F15: =VLOOKUP(B15,Vajda!$A$125:$AG$242,33,FALSE) -> 0 | G15: 460 | H15: =VLOOKUP(B15,Vajda!$A$3:$AG$121,33,FALSE) -> 0 | I15: =(E15*F15)+(G15*H15) -> 0
A16: 12. | B16: =Vajda!A27 -> Balatoni Anita | C16: =VLOOKUP(B16,Vajdanévsor!$A$2:$C$107,2,FALSE) -> X2000010 | D16: =VLOOKUP(B16,Vajdanévsor!$A$2:$C$107,3,FALSE) -> U0000030301 | E16: 380 | F16: =VLOOKUP(B16,Vajda!$A$125:$AG$242,33,FALSE) -> 0 | G16: 460 | H16: =VLOOKUP(B16,Vajda!$A$3:$AG$121,33,FALSE) -> 0 | I16: =(E16*F16)+(G16*H16) -> 0
A17: 13. | B17: =Vajda!A28 -> Erdei Sándorné | C17: =VLOOKUP(B17,Vajdanévsor!$A$2:$C$107,2,FALSE) -> X2000010 | D17: =VLOOKUP(B17,Vajdanévsor!$A$2:$C$107,3,FALSE) -> U0000030301 | E17: 380 | F17: =VLOOKUP(B17,Vajda!$A$125:$AG$242,33,FALSE) -> 0 | G17: 460 | H17: =VLOOKUP(B17,Vajda!$A$3:$AG$121,33,FALSE) -> 0 | I17: =(E17*F17)+(G17*H17) -> 0
A18: 14. | B18: =Vajda!A29 -> Gazsó László | C18: =VLOOKUP(B18,Vajdanévsor!$A$2:$C$107,2,FALSE) -> X2000010 | D18: =VLOOKUP(B18,Vajdanévsor!$A$2:$C$107,3,FALSE) -> U0000030301 | E18: 380 | F18: =VLOOKUP(B18,Vajda!$A$125:$AG$242,33,FALSE) -> 9 | G18: 460 | H18: =VLOOKUP(B18,Vajda!$A$3:$AG$121,33,FALSE) -> 0 | I18: =(E18*F18)+(G18*H18) -> 3420
A19: 15. | B19: =Vajda!A31 -> Molnárné Szappanos Ilona T. | C19: =VLOOKUP(B19,Vajdanévsor!$A$2:$C$107,2,FALSE) -> X2000010 | D19: =VLOOKUP(B19,Vajdanévsor!$A$2:$C$107,3,FALSE) -> U0000030301 | E19: 380 | F19: =VLOOKUP(B19,Vajda!$A$125:$AG$242,33,FALSE) -> 14 | G19: 460 | H19: =VLOOKUP(B19,Vajda!$A$3:$AG$121,33,FALSE) -> 0 | I19: =(E19*F19)+(G19*H19) -> 5320
A20: 16. | B20: =Vajda!A34 -> Kis Gabriella | C20: =VLOOKUP(B20,Vajdanévsor!$A$2:$C$107,2,FALSE) -> X2000025 | D20: =VLOOKUP(B20,Vajdanévsor!$A$2:$C$107,3,FALSE) -> U0000030301 | E20: 380 | F20: =VLOOKUP(B20,Vajda!$A$125:$AG$242,33,FALSE) -> 18 | G20: 460 | H20: =VLOOKUP(B20,Vajda!$A$3:$AG$121,33,FALSE) -> 0 | I20: =(E20*F20)+(G20*H20) -> 6840
A21: 17. | B21: =Vajda!A36 -> Kiszelné Nyemcsok Edit | C21: =VLOOKUP(B21,Vajdanévsor!$A$2:$C$107,2,FALSE) -> X2000025 | D21: =VLOOKUP(B21,Vajdanévsor!$A$2:$C$107,3,FALSE) -> U0000030301 | E21: 380 | F21: =VLOOKUP(B21,Vajda!$A$125:$AG$242,33,FALSE) -> 0 | G21: 460 | H21: =VLOOKUP(B21,Vajda!$A$3:$AG$121,33,FALSE) -> 0 | I21: =(E21*F21)+(G21*H21) -> 0
A22: 18. | B22: =Vajda!A37 -> Krajcsiné Petrov Gabriella | C22: =VLOOKUP(B22,Vajdanévsor!$A$2:$C$107,2,FALSE) -> X2000025 | D22: =VLOOKUP(B22,Vajdanévsor!$A$2:$C$107,3,FALSE) -> U0000030301 | E22: 380 | F22: =VLOOKUP(B22,Vajda!$A$125:$AG$242,33,FALSE) -> 16 | G22: 460 | H22: =VLOOKUP(B22,Vajda!$A$3:$AG$121,33,FALSE) -> 0 | I22: =(E22*F22)+(G22*H22) -> 6080
A23: 19. | B23: =Vajda!A38 -> Stancsikné Hruska Judit | C23: =VLOOKUP(B23,Vajdanévsor!$A$2:$C$107,2,FALSE) -> X2000025 | D23: =VLOOKUP(B23,Vajdanévsor!$A$2:$C$107,3,FALSE) -> U0000030301 | E23: 380 | F23: =VLOOKUP(B23,Vajda!$A$125:$AG$242,33,FALSE) -> 0 | G23: 460 | H23: =VLOOKUP(B23,Vajda!$A$3:$AG$121,33,FALSE) -> 0 | I23: =(E23*F23)+(G23*H23) -> 0
A24: 20. | B24: =Vajda!A41 -> Boldizsár Beáta | C24: =VLOOKUP(B24,Vajdanévsor!$A$2:$C$107,2,FALSE) -> X2000012 | D24: =VLOOKUP(B24,Vajdanévsor!$A$2:$C$107,3,FALSE) -> U0000030301 | E24: 380 | F24: =VLOOKUP(B24,Vajda!$A$125:$AG$242,33,FALSE) -> 0 | G24: 460 | H24: =VLOOKUP(B24,Vajda!$A$3:$AG$121,33,FALSE) -> 0 | I24: =(E24*F24)+(G24*H24) -> 0
A25: 21. | B25: =Vajda!A42 -> Erdei Sándor | C25: =VLOOKUP(B25,Vajdanévsor!$A$2:$C$107,2,FALSE) -> X2000012 | D25: =VLOOKUP(B25,Vajdanévsor!$A$2:$C$107,3,FALSE) -> U0000030301 | E25: 380 | F25: =VLOOKUP(B25,Vajda!$A$125:$AG$242,33,FALSE) -> 20 | G25: 460 | H25: =VLOOKUP(B25,Vajda!$A$3:$AG$121,33,FALSE) -> 0 | I25: =(E25*F25)+(G25*H25) -> 7600
A26: 22. | B26: =Vajda!A43 -> Molnár Andrásné | C26: =VLOOKUP(B26,Vajdanévsor!$A$2:$C$107,2,FALSE) -> X2000012 | D26: =VLOOKUP(B26,Vajdanévsor!$A$2:$C$107,3,FALSE) -> U0000030301 | E26: 380 | F26: =VLOOKUP(B26,Vajda!$A$125:$AG$242,33,FALSE) -> 11 | G26: 460 | H26: =VLOOKUP(B26,Vajda!$A$3:$AG$121,33,FALSE) -> 0 | I26: =(E26*F26)+(G26*H26) -> 4180
A27: 23. | B27: =Vajda!A46 -> Balogh Kálmán | C27: =VLOOKUP(B27,Vajdanévsor!$A$2:$C$107,2,FALSE) -> X8800101 | D27: =VLOOKUP(B27,Vajdanévsor!$A$2:$C$107,3,FALSE) -> U0000030301 | E27: 380 | F27: =VLOOKUP(B27,Vajda!$A$125:$AG$242,33,FALSE) -> 31 | G27: 460 | H27: =VLOOKUP(B27,Vajda!$A$3:$AG$121,33,FALSE) -> 0 | I27: =(E27*F27)+(G27*H27) -> 11780
A28: 24. | B28: =Vajda!A47 -> Benei Martina | C28: =VLOOKUP(B28,Vajdanévsor!$A$2:$C$107,2,FALSE) -> X8800101 | D28: =VLOOKUP(B28,Vajdanévsor!$A$2:$C$107,3,FALSE) -> U0000030301 | E28: 380 | F28: =VLOOKUP(B28,Vajda!$A$125:$AG$242,33,FALSE) -> 0 | G28: 460 | H28: =VLOOKUP(B28,Vajda!$A$3:$AG$121,33,FALSE) -> 0 | I28: =(E28*F28)+(G28*H28) -> 0
A29: 25. | B29: =Vajda!A48 -> ifj. Sárkány János | C29: =VLOOKUP(B29,Vajdanévsor!$A$2:$C$107,2,FALSE) -> X8800101 | D29: =VLOOKUP(B29,Vajdanévsor!$A$2:$C$107,3,FALSE) -> U0000030301 | E29: 380 | F29: =VLOOKUP(B29,Vajda!$A$125:$AG$242,33,FALSE) -> 11 | G29: 460 | H29: =VLOOKUP(B29,Vajda!$A$3:$AG$121,33,FALSE) -> 0 | I29: =(E29*F29)+(G29*H29) -> 4180
A30: 26. | B30: =Vajda!A49 -> Csík Attila | C30: =VLOOKUP(B30,Vajdanévsor!$A$2:$C$107,2,FALSE) -> X8800101 | D30: =VLOOKUP(B30,Vajdanévsor!$A$2:$C$107,3,FALSE) -> U0000030301 | E30: 380 | F30: =VLOOKUP(B30,Vajda!$A$125:$AG$242,33,FALSE) -> 31 | G30: 460 | H30: =VLOOKUP(B30,Vajda!$A$3:$AG$121,33,FALSE) -> 0 | I30: =(E30*F30)+(G30*H30) -> 11780
A31: 27. | B31: =Vajda!A51 -> Harmati Pál | C31: =VLOOKUP(B31,Vajdanévsor!$A$2:$C$107,2,FALSE) -> X8800101 | D31: =VLOOKUP(B31,Vajdanévsor!$A$2:$C$107,3,FALSE) -> U0000030301 | E31: 380 | F31: =VLOOKUP(B31,Vajda!$A$125:$AG$242,33,FALSE) -> 0 | G31: 460 | H31: =VLOOKUP(B31,Vajda!$A$3:$AG$121,33,FALSE) -> 0 | I31: =(E31*F31)+(G31*H31) -> 0
A32: 28. | B32: =Vajda!A52 -> Laurik József | C32: =VLOOKUP(B32,Vajdanévsor!$A$2:$C$107,2,FALSE) -> X8800101 | D32: =VLOOKUP(B32,Vajdanévsor!$A$2:$C$107,3,FALSE) -> U0000030301 | E32: 380 | F32: =VLOOKUP(B32,Vajda!$A$125:$AG$242,33,FALSE) -> 0 | G32: 460 | H32: =VLOOKUP(B32,Vajda!$A$3:$AG$121,33,FALSE) -> 0 | I32: =(E32*F32)+(G32*H32) -> 0
A33: 29. | B33: =Vajda!A53 -> Lázár Zsolt | C33: =VLOOKUP(B33,Vajdanévsor!$A$2:$C$107,2,FALSE) -> X8800101 | D33: =VLOOKUP(B33,Vajdanévsor!$A$2:$C$107,3,FALSE) -> U0000030301 | E33: 380 | F33: =VLOOKUP(B33,Vajda!$A$125:$AG$242,33,FALSE) -> 0 | G33: 460 | H33: =VLOOKUP(B33,Vajda!$A$3:$AG$121,33,FALSE) -> 0 | I33: =(E33*F33)+(G33*H33) -> 0
A34: 30. | B34: =Vajda!A54 -> Medvegy Julianna | C34: =VLOOKUP(B34,Vajdanévsor!$A$2:$C$107,2,FALSE) -> X8800101 | D34: =VLOOKUP(B34,Vajdanévsor!$A$2:$C$107,3,FALSE) -> U0000030301 | E34: 380 | F34: =VLOOKUP(B34,Vajda!$A$125:$AG$242,33,FALSE) -> 0 | G34: 460 | H34: =VLOOKUP(B34,Vajda!$A$3:$AG$121,33,FALSE) -> 0 | I34: =(E34*F34)+(G34*H34) -> 0
A35: 31. | B35: =Vajda!A55 -> Portik Andrea | C35: =VLOOKUP(B35,Vajdanévsor!$A$2:$C$107,2,FALSE) -> X8800101 | D35: =VLOOKUP(B35,Vajdanévsor!$A$2:$C$107,3,FALSE) -> U0000030301 | E35: 380 | F35: =VLOOKUP(B35,Vajda!$A$125:$AG$242,33,FALSE) -> 16 | G35: 460 | H35: =VLOOKUP(B35,Vajda!$A$3:$AG$121,33,FALSE) -> 0 | I35: =(E35*F35)+(G35*H35) -> 6080
A36: 32. | B36: =Vajda!A56 -> Sárkány János | C36: =VLOOKUP(B36,Vajdanévsor!$A$2:$C$107,2,FALSE) -> X8800101 | D36: =VLOOKUP(B36,Vajdanévsor!$A$2:$C$107,3,FALSE) -> U0000030301 | E36: 380 | F36: =VLOOKUP(B36,Vajda!$A$125:$AG$242,33,FALSE) -> 20 | G36: 460 | H36: =VLOOKUP(B36,Vajda!$A$3:$AG$121,33,FALSE) -> 0 | I36: =(E36*F36)+(G36*H36) -> 7600
A37: 33. | B37: =Vajda!A57 -> Sindely Imréné | C37: =VLOOKUP(B37,Vajdanévsor!$A$2:$C$107,2,FALSE) -> X8800101 | D37: =VLOOKUP(B37,Vajdanévsor!$A$2:$C$107,3,FALSE) -> U0000030301 | E37: 380 | F37: =VLOOKUP(B37,Vajda!$A$125:$AG$242,33,FALSE) -> 0 | G37: 460 | H37: =VLOOKUP(B37,Vajda!$A$3:$AG$121,33,FALSE) -> 0 | I37: =(E37*F37)+(G37*H37) -> 0
A38: 34. | B38: =Vajda!A58 -> Tóthné Tótka Edit | C38: =VLOOKUP(B38,Vajdanévsor!$A$2:$C$107,2,FALSE) -> X8800101 | D38: =VLOOKUP(B38,Vajdanévsor!$A$2:$C$107,3,FALSE) -> U0000030301 | E38: 380 | F38: =VLOOKUP(B38,Vajda!$A$125:$AG$242,33,FALSE) -> 0 | G38: 460 | H38: =VLOOKUP(B38,Vajda!$A$3:$AG$121,33,FALSE) -> 0 | I38: =(E38*F38)+(G38*H38) -> 0
A39: 35. | B39: =Vajda!A59 -> Túróczi Rudolfné | C39: =VLOOKUP(B39,Vajdanévsor!$A$2:$C$107,2,FALSE) -> X8800101 | D39: =VLOOKUP(B39,Vajdanévsor!$A$2:$C$107,3,FALSE) -> U0000030301 | E39: 380 | F39: =VLOOKUP(B39,Vajda!$A$125:$AG$242,33,FALSE) -> 0 | G39: 460 | H39: =VLOOKUP(B39,Vajda!$A$3:$AG$121,33,FALSE) -> 0 | I39: =(E39*F39)+(G39*H39) -> 0
A40: 36. | B40: =Vajda!A60 -> Varga Katalin | C40: =VLOOKUP(B40,Vajdanévsor!$A$2:$C$107,2,FALSE) -> X8800101 | D40: =VLOOKUP(B40,Vajdanévsor!$A$2:$C$107,3,FALSE) -> U0000030301 | E40: 380 | F40: =VLOOKUP(B40,Vajda!$A$125:$AG$242,33,FALSE) -> 0 | G40: 460 | H40: =VLOOKUP(B40,Vajda!$A$3:$AG$121,33,FALSE) -> 0 | I40: =(E40*F40)+(G40*H40) -> 0
...

Sheet Vajdanévsor
A1: Név | B1: xkód | C1: ukód
A2: Láng Emese | B2: X2000037 | C2: U0000030301
A3: Galó Tamás | B3: X2000037 | C3: U0000030301
A4: Molnár Pál | B4: X2000037 | C4: U0000030301
A5: Csire Melinda | B5: X2000014 | C5: U0000030301
A6: Fülepi Aranka | B6: X2100001 | C6: U0000030301
A7: Pribelszki András | B7: X2000004 | C7: U0000030301
A8: Kelemen Márta | B8: X2000004 | C8: U0000030301
A9: Valyó András | B9: X2000004 | C9: U0000030301
A10: Mucha Mónika | B10: X2000004 | C10: U0000030301
A11: Tőkés Nikolett | B11: X2000004 | C11: U0000030301
A12: Maczik Anna | B12: X2000004 | C12: U0000030301
... A14: Himmer Péter | B14: X2000004 | C14: U0000030301
A15: 0
A16: 0
A17: Balatoni Anita | B17: X2000010 | C17: U0000030301
A18: Erdei Sándorné | B18: X2000010 | C18: U0000030301
A19: Gazsó László | B19: X2000010 | C19: U0000030301
A20: Molnárné Szappanos Ilona T. | B20: X2000010 | C20: U0000030301
A21: Kis Gabriella | B21: X2000025 | C21: U0000030301
A22: Kiszelné Nyemcsok Edit | B22: X2000025 | C22: U0000030301
A23: Krajcsiné Petrov Gabriella | B23: X2000025 | C23: U0000030301
A24: Stancsikné Hruska Judit | B24: X2000025 | C24: U0000030301
A25: Boldizsár Beáta | B25: X2000012 | C25: U0000030301
